Workbook
Name capex: чувствительность!$B$5
Name cur: данные!$A$2
Name discont: СВОД!$B$27
Name fot: СВОД!$B$16
Name fotmes: СВОД!$C$16
Name price: чувствительность!$B$7
Name profittax: СВОД!$B$22
Name proptax: СВОД!$B$24
Name raw: чувствительность!$B$8
Name salarytax: СВОД!$B$25
Name title: данные!$A$1
Name var: СВОД!$C$3
Name vat: СВОД!$B$23
Name volume: чувствительность!$B$6

Sheet СВОД
A1: Исходные данные | F1: Сводные результаты | G1: http://exceltable.com/
A3: Вариант | C3: 1 | D3: 1
D4: 2 | F4: млн. USD
A5: Данные по вариантам | B5: Вар.1 | C5: Вар.2 | F5: =title -> Вариант 1 | G5: Сумма | H5: 2014 | I5: 2015 | J5: 2016 | K5: 2017 | L5: 2018 | M5: 2019 | N5: 2020 | O5: 2021 | P5: 2022 | Q5: 2023 | R5: 2024
A6: Сырьё | F6: Валовый объем продаж (с НДС) | G6: =SUM(H6:R6) -> 6500.9942 | H6: ='Cash Flow'!D55 -> 0 | I6: ='Cash Flow'!E55 -> 228.3525 | J6: ='Cash Flow'!F55 -> 568.86637 | K6: ='Cash Flow'!G55 -> 597.30969 | L6: ='Cash Flow'!H55 -> 627.17518 | M6: ='Cash Flow'!I55 -> 658.53394 | N6: ='Cash Flow'!J55 -> 691.46063 | O6: ='Cash Flow'!K55 -> 726.03367 | ... R6: ='Cash Flow'!N55 -> 840.47472
A7: сырье 1 | B7: 1 | C7: 0.7 | F7: Чистый объем продаж (без НДС) | G7: =SUM(H7:R7) -> 5509.3171 | H7: =PL!D24 -> 0 | I7: =PL!E24 -> 193.51907 | J7: =PL!F24 -> 482.09015 | K7: =PL!G24 -> 506.19466 | L7: =PL!H24 -> 531.50439 | M7: =PL!I24 -> 558.07961 | N7: =PL!J24 -> 585.98359 | O7: =PL!K24 -> 615.28277 | ... R7: =PL!N24 -> 712.26671
A8: сырье 2 | B8: =1-B7 -> 0 | C8: =1-C7 -> 0.3 | F8: Суммарные прямые издержки | G8: =SUM(H8:R8) -> 3767.9449 | H8: =PL!D25 -> 0 | I8: =PL!E25 -> 133.05085 | J8: =PL!F25 -> 331.14407 | K8: =PL!G25 -> 347.29449 | L8: =PL!H25 -> 364.25244 | M8: =PL!I25 -> 382.05828 | N8: =PL!J25 -> 400.75441 | O8: =PL!K25 -> 420.38535 | ... R8: =PL!N25 -> 485.36622
A9: Выход продукции | F9: Суммарные постоянные издержки | G9: =SUM(H9:R9) -> 78.693874 | H9: =PL!D27+PL!D28+PL!D29 -> 0 | I9: =PL!E27+PL!E28 -> 3.6936155 | J9: =PL!F27+PL!F28 -> 8.023858 | K9: =PL!G27+PL!G28 -> 8.101234 | L9: =PL!H27+PL!H28 -> 8.17861 | M9: =PL!I27+PL!I28 -> 8.255986 | N9: =PL!J27+PL!J28 -> 8.333362 | O9: =PL!K27+PL!K28 -> 8.410738 | P9: =PL!L27+PL!L28 -> 8.488114 | ... R9: =PL!N27+PL!N28 -> 8.642866
A10: продукт 1 | B10: 0.7 | C10: 0.5 | F10: Амортизация | G10: =SUM(H10:R10) -> 55.492828 | H10: =PL!D34 -> 0 | I10: =PL!E34 -> 2.5631163 | J10: =PL!F34 -> 5.8810791 | K10: =PL!G34 -> 5.8810791 | L10: =PL!H34 -> 5.8810791 | M10: =PL!I34 -> 5.8810791 | N10: =PL!J34 -> 5.8810791 | O10: =PL!K34 -> 5.8810791 | ... R10: =PL!N34 -> 5.8810791
A11: продукт 2 | B11: 0.23 | C11: 0.4 | F11: Затраты на приобретение активов | G11: =SUM(H11:R11) -> 82.18818 | H11: =-'Cash Flow'!D73 -> 52.36268 | I11: =-'Cash Flow'!E73 -> 29.8255 | J11: =-'Cash Flow'!F73 -> 0 | K11: =-'Cash Flow'!G73 -> 0 | L11: =-'Cash Flow'!H73 -> 0 | M11: =-'Cash Flow'!I73 -> 0 | N11: =-'Cash Flow'!J73 -> 0 | O11: =-'Cash Flow'!K73 -> 0 | ... R11: =-'Cash Flow'!N73 -> 0
A12: продукт 3 | B12: 0 | C12: 0.05 | F12: Займы | G12: =SUM(H12:R12) -> 87.1 | H12: ='Cash Flow'!D78 -> 53.2 | I12: ='Cash Flow'!E78 -> 33.9 | J12: ='Cash Flow'!F78 -> 0 | K12: ='Cash Flow'!G78 -> 0 | L12: ='Cash Flow'!H78 -> 0 | M12: ='Cash Flow'!I78 -> 0 | N12: ='Cash Flow'!J78 -> 0 | O12: ='Cash Flow'!K78 -> 0 | ... R12: ='Cash Flow'!N78 -> 0
F13: Выплаты в погашение займов | G13: =SUM(H13:R13) -> 87.1 | H13: ='Cash Flow'!D80 -> 0 | I13: ='Cash Flow'!E80 -> 24.885714 | J13: ='Cash Flow'!F80 -> 62.214286 | K13: ='Cash Flow'!G80 -> 0 | L13: ='Cash Flow'!H80 -> 0 | M13: ='Cash Flow'!I80 -> 0 | N13: ='Cash Flow'!J80 -> 0 | O13: ='Cash Flow'!K80 -> 0 | ... R13: ='Cash Flow'!N80 -> 0
A14: Рост цены на продукцию, % в год | B14: 0.05 | F14: Выплаты процентов по займам | G14: =SUM(H14:R14) -> 8.7891667 | H14: ='Cash Flow'!D81 -> 0 | I14: ='Cash Flow'!E81 -> 7.2338095 | J14: ='Cash Flow'!F81 -> 1.5553571 | K14: ='Cash Flow'!G81 -> 0 | L14: ='Cash Flow'!H81 -> 0 | M14: ='Cash Flow'!I81 -> 0 | N14: ='Cash Flow'!J81 -> 0 | O14: ='Cash Flow'!K81 -> 0 | ... R14: ='Cash Flow'!N81 -> 0
A15: Рост цены на сырье, % в год | B15: 0.05 | F15: Налоги | G15: =SUM(H15:R15) -> 616.72746 | H15: ='Cash Flow'!D63 -> 0 | I15: ='Cash Flow'!E63 -> 9.5541447 | J15: ='Cash Flow'!F63 -> 50.100204 | K15: ='Cash Flow'!G63 -> 57.784063 | L15: ='Cash Flow'!H63 -> 60.832454 | M15: ='Cash Flow'!I63 -> 64.039213 | N15: ='Cash Flow'!J63 -> 67.412259 | O15: ='Cash Flow'!K63 -> 70.959907 | ... R15: ='Cash Flow'!N63 -> 82.739963
A16: Индексация ФОТ, % в год | B16: 0.02 | C16: =POWER(1+fot,1/12)-1 -> 0.0016515813 | F16: Чистая прибыль | G16: =SUM(H16:R16) -> 1271.8091 | H16: =PL!D39 -> -0.084559322 | I16: =PL!E39 -> 37.423534 | J16: =PL!F39 -> 107.22464 | K16: =PL!G39 -> 114.88441 | L16: =PL!H39 -> 121.60744 | M16: =PL!I39 -> 128.66455 | N16: =PL!J39 -> 136.07243 | O16: =PL!K39 -> 143.84863 | ... R16: =PL!N39 -> 169.57591
F17: Баланс наличности на конец периода | G17: =R17 -> 1236.6902 | H17: ='Cash Flow'!D86 -> 0.83732 | I17: ='Cash Flow'!E86 -> 14.377665 | J17: ='Cash Flow'!F86 -> 69.087557 | K17: ='Cash Flow'!G86 -> 189.1523 | L17: ='Cash Flow'!H86 -> 315.90504 | M17: ='Cash Flow'!I86 -> 449.67811 | N17: ='Cash Flow'!J86 -> 590.82042 | O17: ='Cash Flow'!K86 -> 739.69838 | ... R17: ='Cash Flow'!N86 -> 1236.6902
A18: Срок кредита | B18: Вар.1 | C18: Вар.2
A19: Срок | B19: 18 | C19: 30 | F19: =IF(L30=C30,"","ДЛЯ РАСЧЁТА НАЖАТЬ F9")
F20: Показатели | H20: варианты | J20: ! Для обновления при смене исходных данных нажать F9
A21: Налоги | B21: Ставка | H21: 1 | I21: 2
A22: Налог на прибыль | B22: 0.2 | F22: Чистая текущая стоимость (NPV), млн. USD | G22: =NPV!C11/1000000 -> 415.40684 | H22: 415.40684 | I22: 436.16541
A23: НДС | B23: 0.18 | F23: Внутренняя ставка доходности (IRR), % | G23: =NPV!C12 -> 1.3290017 | H23: 1.3290017 | I23: 1.381781
A24: Налог на имущество | B24: 0.022 | F24: Индекс доходности (PI) | G24: =NPV!C13 -> 3.5754771 | H24: 3.5754771 | I24: 3.7535218
A25: Налог на ФОТ | B25: 0.3 | F25: Срок окупаемости (PBP), мес. | G25: =NPV!C14 -> 18 | H25: 18 | I25: 18
F26: Дисконт. срок окупаемости (DPBP), мес. | G26: =NPV!C15 -> 21 | H26: 21 | I26: 20
A27: Ставка дисконтирования | B27: 0.25
B31: =чувствительность!G7 -> 0.8 | C31: =чувствительность!H7 -> 0.85 | D31: =чувствительность!I7 -> 0.9 | E31: =чувствительность!J7 -> 0.95 | F31: =чувствительность!K7 -> 1 | G31: =чувствительность!L7 -> 1.05 | H31: =чувствительность!M7 -> 1.1 | I31: =чувствительность!N7 -> 1.15 | J31: =чувствительность!O7 -> 1.2
A32: =чувствительность!A5 -> Кап. затраты | B32: =чувствительность!G53 -> 1.360834 | C32: =чувствительность!H53 -> 1.3527878 | D32: =чувствительность!I53 -> 1.344769 | E32: =чувствительность!J53 -> 1.3368447 | F32: =чувствительность!K53 -> 1.3290017 | G32: =чувствительность!L53 -> 1.3210485 | H32: =чувствительность!M53 -> 1.3132094 | I32: =чувствительность!N53 -> 1.3054865 | J32: =чувствительность!O53 -> 1.2977291
A33: =чувствительность!A6 -> Объем переработки | B33: =чувствительность!G59 -> 1.0769928 | C33: =чувствительность!H59 -> 1.1404982 | D33: =чувствительность!I59 -> 1.2035974 | E33: =чувствительность!J59 -> 1.2664137 | F33: =чувствительность!K59 -> 1.3290017 | G33: =чувствительность!L59 -> 1.3911396 | H33: =чувствительность!M59 -> 1.4529995 | I33: =чувствительность!N59 -> 1.514662 | J33: =чувствительность!O59 -> 1.5760659
A34: =чувствительность!A7 -> Цена | B34: =чувствительность!G65 -> 0.46234317 | C34: =чувствительность!H65 -> 0.67446322 | D34: =чувствительность!I65 -> 0.88884841 | E34: =чувствительность!J65 -> 1.1071878 | F34: =чувствительность!K65 -> 1.3290017 | G34: =чувствительность!L65 -> 1.5533933 | H34: =чувствительность!M65 -> 1.7796404 | I34: =чувствительность!N65 -> 2.0076832 | J34: =чувствительность!O65 -> 2.2369593
A35: =чувствительность!A8 -> Стоимость сырья | B35: =чувствительность!G71 -> 1.9738622 | C35: =чувствительность!H71 -> 1.8097327 | D35: =чувствительность!I71 -> 1.6473765 | E35: =чувствительность!J71 -> 1.4870375 | F35: =чувствительность!K71 -> 1.3290017 | G35: =чувствительность!L71 -> 1.1733646 | H35: =чувствительность!M71 -> 1.0205575 | I35: =чувствительность!N71 -> 0.87093314 | J35: =чувствительность!O71 -> 0.72472355
A44: ! Для обновления при смене вариантов нажать F9

Sheet данные
A1: ="Вариант "&var -> Вариант 1 | B1: http://exceltable.com/ | D1: 1 | E1: 2 | F1: 3 | G1: 4 | H1: 5 | I1: 6 | J1: 7 | K1: 8 | L1: 9 | M1: 10 | N1: 11 | O1: 12 | P1: 13 | Q1: 14 | R1: 15 | S1: 16 | T1: 17 | U1: 18 | V1: 19 | W1: 20 | X1: 21 | Y1: 22 | Z1: 23 | AA1: 24 | AB1: 25 | AC1: 26 | AD1: 27 | AE1: 28 | AF1: 29 | AG1: 30 | AH1: 31 | AI1: 32 | AJ1: 33 | AK1: 34 | AL1: 35 | AM1: 36 | AN1: 37 | AO1: 38 | AP1: 39 | AQ1: 40 | AR1: 41 | AS1: 42 | AT1: 43 | AU1: 44 | AV1: 45 | AW1: 46 | AX1: 47 | AY1: 48 | AZ1: 49 | BA1: 50 | BB1: 51 | BC1: 52 | BD1: 53 | BE1: 54 | BF1: 55 | BG1: 56 | BH1: 57 | BI1: 58 | BJ1: 59 | BK1: 60 | BL1: 61 | BM1: 62 | BN1: 63 | BO1: 64 | BP1: 65 | BQ1: 66 | BR1: 67 | BS1: 68 | BT1: 69 | BU1: 70 | BV1: 71 | BW1: 72 | BX1: 73 | BY1: 74 | BZ1: 75 | CA1: 76 | CB1: 77 | CC1: 78 | CD1: 79 | CE1: 80 | CF1: 81 | CG1: 82 | CH1: 83 | CI1: 84 | CJ1: 85 | CK1: 86 | CL1: 87 | CM1: 88 | CN1: 89 | CO1: 90 | CP1: 91 | CQ1: 92 | CR1: 93 | CS1: 94 | CT1: 95 | CU1: 96 | CV1: 97 | CW1: 98 | CX1: 99 | CY1: 100 | CZ1: 101 | DA1: 102 | DB1: 103 | DC1: 104 | DD1: 105 | DE1: 106 | DF1: 107 | DG1: 108 | DH1: 109 | DI1: 110 | DJ1: 111 | DK1: 112 | DL1: 113 | DM1: 114 | DN1: 115 | DO1: 116 | DP1: 117 | DQ1: 118 | DR1: 119 | DS1: 120 | DT1: 121 | DU1: 122
A2: USD | D2: =YEAR(D3) -> 2014 | E2: =YEAR(E3) -> 2014 | F2: =YEAR(F3) -> 2015 | G2: =YEAR(G3) -> 2015 | H2: =YEAR(H3) -> 2015 | I2: =YEAR(I3) -> 2015 | J2: =YEAR(J3) -> 2015 | K2: =YEAR(K3) -> 2015 | ... DU2: =YEAR(DU3) -> 2024
A3: Капитальные затраты | C3: Сумма | D3: 41944 | E3: 41974 | F3: 42005 | G3: 42036 | H3: 42064 | I3: 42095 | J3: 42125 | K3: 42156 | L3: 42186 | M3: 42217 | N3: 42248 | O3: 42278 | P3: 42309 | Q3: 42339 | R3: 42370 | S3: 42401 | T3: 42430 | U3: 42461 | V3: 42491 | W3: 42522 | X3: 42552 | Y3: 42583 | Z3: 42614 | AA3: 42644 | AB3: 42675 | AC3: 42705 | AD3: 42736 | AE3: 42767 | AF3: 42795 | AG3: 42826 | AH3: 42856 | AI3: 42887 | AJ3: 42917 | AK3: 42948 | AL3: 42979 | AM3: 43009 | AN3: 43040 | AO3: 43070 | AP3: 43101 | AQ3: 43132 | AR3: 43160 | AS3: 43191 | AT3: 43221 | AU3: 43252 | AV3: 43282 | AW3: 43313 | AX3: 43344 | AY3: 43374 | AZ3: 43405 | BA3: 43435 | BB3: 43466 | BC3: 43497 | BD3: 43525 | BE3: 43556 | BF3: 43586 | BG3: 43617 | BH3: 43647 | BI3: 43678 | BJ3: 43709 | BK3: 43739 | BL3: 43770 | BM3: 43800 | BN3: 43831 | BO3: 43862 | BP3: 43891 | BQ3: 43922 | BR3: 43952 | BS3: 43983 | BT3: 44013 | BU3: 44044 | BV3: 44075 | BW3: 44105 | BX3: 44136 | BY3: 44166 | BZ3: 44197 | CA3: 44228 | CB3: 44256 | CC3: 44287 | CD3: 44317 | CE3: 44348 | CF3: 44378 | CG3: 44409 | CH3: 44440 | CI3: 44470 | CJ3: 44501 | CK3: 44531 | CL3: 44562 | CM3: 44593 | CN3: 44621 | CO3: 44652 | CP3: 44682 | CQ3: 44713 | CR3: 44743 | CS3: 44774 | CT3: 44805 | CU3: 44835 | CV3: 44866 | CW3: 44896 | CX3: 44927 | CY3: 44958 | CZ3: 44986 | DA3: 45017 | DB3: 45047 | DC3: 45078 | DD3: 45108 | DE3: 45139 | DF3: 45170 | DG3: 45200 | DH3: 45231 | DI3: 45261 | DJ3: 45292 | DK3: 45323 | DL3: 45352 | DM3: 45383 | DN3: 45413 | DO3: 45444 | DP3: 45474 | DQ3: 45505 | DR3: 45536 | DS3: 45566 | DT3: 45597 | DU3: 45627
A4: capex 1 | C4: =SUM(D4:DU4) -> 65000000 | D4: 45000000 | E4: 0 | F4: 0 | G4: 0 | H4: 0 | I4: 0 | J4: 0 | K4: 0 | L4: 0 | M4: 20000000
A5: capex 2 | C5: =SUM(D5:DU5) -> 608400 | D5: 432900 | E5: 0 | F5: 0 | G5: 0 | H5: 175500 | I5: 0 | J5: 0 | K5: 0 | L5: 0 | M5: 0
A6: capex 3 | C6: =SUM(D6:DU6) -> 39780 | D6: 39780 | E6: 0 | F6: 0 | G6: 0 | H6: 0 | I6: 0 | J6: 0 | K6: 0 | L6: 0 | M6: 0
A7: capex 4 | C7: =SUM(D7:DU7) -> 3230000 | D7: 120000 | E7: 120000 | F7: 120000 | G7: 120000 | H7: 550000 | I7: 550000 | J7: 550000 | K7: 550000 | L7: 550000 | M7: 0
A8: capex 5 | C8: =SUM(D8:DU8) -> 60000 | D8: 60000 | E8: 0 | F8: 0 | G8: 0 | H8: 0 | I8: 0 | J8: 0 | K8: 0 | L8: 0 | M8: 0
A9: capex 6 | C9: =SUM(D9:DU9) -> 8100000 | D9: 900000 | E9: 900000 | F9: 900000 | G9: 900000 | H9: 900000 | I9: 900000 | J9: 900000 | K9: 900000 | L9: 900000 | M9: 0
A10: capex 7 | C10: =SUM(D10:DU10) -> 2500000 | D10: 2500000 | E10: 0 | F10: 0 | G10: 0 | H10: 0 | I10: 0 | J10: 0 | K10: 0 | L10: 0 | M10: 0
A11: capex 8 | C11: =SUM(D11:DU11) -> 2200000 | D11: 2200000 | E11: 0 | F11: 0 | G11: 0 | H11: 0 | I11: 0 | J11: 0 | K11: 0 | L11: 0 | M11: 0
A12: capex 9 | C12: =SUM(D12:DU12) -> 450000 | D12: 45000 | E12: 45000 | F12: 45000 | G12: 45000 | H12: 45000 | I12: 45000 | J12: 45000 | K12: 45000 | L12: 45000 | M12: 45000
A13: ИТОГО | C13: =SUM(D13:DU13) -> 82188180 | D13: =SUM(D4:D12)*capex -> 51297680 | E13: =SUM(E4:E12)*capex -> 1065000 | F13: =SUM(F4:F12)*capex -> 1065000 | G13: =SUM(G4:G12)*capex -> 1065000 | H13: =SUM(H4:H12)*capex -> 1670500 | I13: =SUM(I4:I12)*capex -> 1495000 | J13: =SUM(J4:J12)*capex -> 1495000 | K13: =SUM(K4:K12)*capex -> 1495000 | ... DU13: =SUM(DU4:DU12)*capex -> 0
A16: Амортизация | C16: Сумма | D16: =D3 -> 41944 | E16: =E3 -> 41974 | F16: =F3 -> 42005 | G16: =G3 -> 42036 | H16: =H3 -> 42064 | I16: =I3 -> 42095 | J16: =J3 -> 42125 | K16: =K3 -> 42156 | ... DU16: =DU3 -> 45627
A17: Первонач. стоимость | B17: пуск | D17: =SUM(D18:D26) -> 0 | E17: =SUM(E18:E26) -> 0 | F17: =SUM(F18:F26) -> 0 | G17: =SUM(G18:G26) -> 0 | H17: =SUM(H18:H26) -> 0 | I17: =SUM(I18:I26) -> 4498644.1 | J17: =SUM(J18:J26) -> 4498644.1 | K17: =SUM(K18:K26) -> 4498644.1 | ... DU17: =SUM(DU18:DU26) -> 69566441
A18: =A4 -> capex 1 | B18: 10 | D18: =IF($B18<=D$1,$C4/(1+vat),0) -> 0 | E18: =IF($B18<=E$1,$C4/(1+vat),0) -> 0 | F18: =IF($B18<=F$1,$C4/(1+vat),0) -> 0 | G18: =IF($B18<=G$1,$C4/(1+vat),0) -> 0 | H18: =IF($B18<=H$1,$C4/(1+vat),0) -> 0 | I18: =IF($B18<=I$1,$C4/(1+vat),0) -> 0 | J18: =IF($B18<=J$1,$C4/(1+vat),0) -> 0 | K18: =IF($B18<=K$1,$C4/(1+vat),0) -> 0 | ... DU18: =IF($B18<=DU$1,$C4/(1+vat),0) -> 55084746
A19: =A5 -> capex 2 | B19: 6 | D19: =IF($B19<=D$1,$C5/(1+vat),0) -> 0 | E19: =IF($B19<=E$1,$C5/(1+vat),0) -> 0 | F19: =IF($B19<=F$1,$C5/(1+vat),0) -> 0 | G19: =IF($B19<=G$1,$C5/(1+vat),0) -> 0 | H19: =IF($B19<=H$1,$C5/(1+vat),0) -> 0 | I19: =IF($B19<=I$1,$C5/(1+vat),0) -> 515593.22 | J19: =IF($B19<=J$1,$C5/(1+vat),0) -> 515593.22 | K19: =IF($B19<=K$1,$C5/(1+vat),0) -> 515593.22 | ... DU19: =IF($B19<=DU$1,$C5/(1+vat),0) -> 515593.22
A21: =A7 -> capex 4 | B21: 10 | D21: =IF($B21<=D$1,$C7/(1+vat),0) -> 0 | E21: =IF($B21<=E$1,$C7/(1+vat),0) -> 0 | F21: =IF($B21<=F$1,$C7/(1+vat),0) -> 0 | G21: =IF($B21<=G$1,$C7/(1+vat),0) -> 0 | H21: =IF($B21<=H$1,$C7/(1+vat),0) -> 0 | I21: =IF($B21<=I$1,$C7/(1+vat),0) -> 0 | J21: =IF($B21<=J$1,$C7/(1+vat),0) -> 0 | K21: =IF($B21<=K$1,$C7/(1+vat),0) -> 0 | ... DU21: =IF($B21<=DU$1,$C7/(1+vat),0) -> 2737288.1
A23: =A9 -> capex 6 | B23: 10 | D23: =IF($B23<=D$1,$C9/(1+vat),0) -> 0 | E23: =IF($B23<=E$1,$C9/(1+vat),0) -> 0 | F23: =IF($B23<=F$1,$C9/(1+vat),0) -> 0 | G23: =IF($B23<=G$1,$C9/(1+vat),0) -> 0 | H23: =IF($B23<=H$1,$C9/(1+vat),0) -> 0 | I23: =IF($B23<=I$1,$C9/(1+vat),0) -> 0 | J23: =IF($B23<=J$1,$C9/(1+vat),0) -> 0 | K23: =IF($B23<=K$1,$C9/(1+vat),0) -> 0 | ... DU23: =IF($B23<=DU$1,$C9/(1+vat),0) -> 6864406.8
A24: =A10 -> capex 7 | B24: 6 | D24: =IF($B24<=D$1,$C10/(1+vat),0) -> 0 | E24: =IF($B24<=E$1,$C10/(1+vat),0) -> 0 | F24: =IF($B24<=F$1,$C10/(1+vat),0) -> 0 | G24: =IF($B24<=G$1,$C10/(1+vat),0) -> 0 | H24: =IF($B24<=H$1,$C10/(1+vat),0) -> 0 | I24: =IF($B24<=I$1,$C10/(1+vat),0) -> 2118644.1 | J24: =IF($B24<=J$1,$C10/(1+vat),0) -> 2118644.1 | K24: =IF($B24<=K$1,$C10/(1+vat),0) -> 2118644.1 | ... DU24: =IF($B24<=DU$1,$C10/(1+vat),0) -> 2118644.1
A25: =A11 -> capex 8 | B25: 6 | D25: =IF($B25<=D$1,$C11/(1+vat),0) -> 0 | E25: =IF($B25<=E$1,$C11/(1+vat),0) -> 0 | F25: =IF($B25<=F$1,$C11/(1+vat),0) -> 0 | G25: =IF($B25<=G$1,$C11/(1+vat),0) -> 0 | H25: =IF($B25<=H$1,$C11/(1+vat),0) -> 0 | I25: =IF($B25<=I$1,$C11/(1+vat),0) -> 1864406.8 | J25: =IF($B25<=J$1,$C11/(1+vat),0) -> 1864406.8 | K25: =IF($B25<=K$1,$C11/(1+vat),0) -> 1864406.8 | ... DU25: =IF($B25<=DU$1,$C11/(1+vat),0) -> 1864406.8
A26: =A12 -> capex 9 | B26: 10 | D26: =IF($B26<=D$1,$C12/(1+vat),0) -> 0 | E26: =IF($B26<=E$1,$C12/(1+vat),0) -> 0 | F26: =IF($B26<=F$1,$C12/(1+vat),0) -> 0 | G26: =IF($B26<=G$1,$C12/(1+vat),0) -> 0 | H26: =IF($B26<=H$1,$C12/(1+vat),0) -> 0 | I26: =IF($B26<=I$1,$C12/(1+vat),0) -> 0 | J26: =IF($B26<=J$1,$C12/(1+vat),0) -> 0 | K26: =IF($B26<=K$1,$C12/(1+vat),0) -> 0 | ... DU26: =IF($B26<=DU$1,$C12/(1+vat),0) -> 381355.93
A27: Незавершенное стр-во | D27: =SUM(D4:D5,D7,D9:D12)/(1+vat)-D17 -> 43388051 | E27: =MAX(0,SUM($D$4:E5,$D$7:E7,$D$9:E12)/(1+vat)-E17) -> 44290593 | F27: =MAX(0,SUM($D$4:F5,$D$7:F7,$D$9:F12)/(1+vat)-F17) -> 45193136 | G27: =MAX(0,SUM($D$4:G5,$D$7:G7,$D$9:G12)/(1+vat)-G17) -> 46095678 | H27: =MAX(0,SUM($D$4:H5,$D$7:H7,$D$9:H12)/(1+vat)-H17) -> 47511356 | I27: =MAX(0,SUM($D$4:I5,$D$7:I7,$D$9:I12)/(1+vat)-I17) -> 44279661 | J27: =MAX(0,SUM($D$4:J5,$D$7:J7,$D$9:J12)/(1+vat)-J17) -> 45546610 | K27: =MAX(0,SUM($D$4:K5,$D$7:K7,$D$9:K12)/(1+vat)-K17) -> 46813559 | L27: =MAX(0,SUM($D$4:L5,$D$7:L7,$D$9:L12)/(1+vat)-L17) -> 48080508 | ... DU27: =MAX(0,SUM($D$4:DU5,$D$7:DU7,$D$9:DU12)/(1+vat)-DU17) -> 0
A28: Амортизация | B28: ставка | D28: =SUM(D29:D35) -> 0 | E28: =SUM(E29:E35) -> 0 | F28: =SUM(F29:F35) -> 0 | G28: =SUM(G29:G35) -> 0 | H28: =SUM(H29:H35) -> 0 | I28: =SUM(I29:I35) -> 28166.667 | J28: =SUM(J29:J35) -> 28166.667 | K28: =SUM(K29:K35) -> 28166.667 | ... DU28: =SUM(DU29:DU35) -> 490089.92
A29: =A4 -> capex 1 | B29: =1/12 -> 0.083333333 | D29: =D18*$B29/12 -> 0 | E29: =E18*$B29/12 -> 0 | F29: =F18*$B29/12 -> 0 | G29: =G18*$B29/12 -> 0 | H29: =H18*$B29/12 -> 0 | I29: =I18*$B29/12 -> 0 | J29: =J18*$B29/12 -> 0 | K29: =K18*$B29/12 -> 0 | ... DU29: =DU18*$B29/12 -> 382532.96
A30: =A5 -> capex 2 | B30: =1/10 -> 0.1 | D30: =D19*$B30/12 -> 0 | E30: =E19*$B30/12 -> 0 | F30: =F19*$B30/12 -> 0 | G30: =G19*$B30/12 -> 0 | H30: =H19*$B30/12 -> 0 | I30: =I19*$B30/12 -> 4296.6102 | J30: =J19*$B30/12 -> 4296.6102 | K30: =K19*$B30/12 -> 4296.6102 | ... DU30: =DU19*$B30/12 -> 4296.6102
A31: =A7 -> capex 4 | B31: =1/12 -> 0.083333333 | D31: =D21*$B31/12 -> 0 | E31: =E21*$B31/12 -> 0 | F31: =F21*$B31/12 -> 0 | G31: =G21*$B31/12 -> 0 | H31: =H21*$B31/12 -> 0 | I31: =I21*$B31/12 -> 0 | J31: =J21*$B31/12 -> 0 | K31: =K21*$B31/12 -> 0 | ... DU31: =DU21*$B31/12 -> 19008.945
A32: =A9 -> capex 6 | B32: =1/10 -> 0.1 | D32: =D23*$B32/12 -> 0 | E32: =E23*$B32/12 -> 0 | F32: =F23*$B32/12 -> 0 | G32: =G23*$B32/12 -> 0 | H32: =H23*$B32/12 -> 0 | I32: =I23*$B32/12 -> 0 | J32: =J23*$B32/12 -> 0 | K32: =K23*$B32/12 -> 0 | ... DU32: =DU23*$B32/12 -> 57203.39
A33: =A10 -> capex 7 | B33: =1/10 -> 0.1 | D33: =D24*$B33/12 -> 0 | E33: =E24*$B33/12 -> 0 | F33: =F24*$B33/12 -> 0 | G33: =G24*$B33/12 -> 0 | H33: =H24*$B33/12 -> 0 | I33: =I24*$B33/12 -> 17655.367 | J33: =J24*$B33/12 -> 17655.367 | K33: =K24*$B33/12 -> 17655.367 | ... DU33: =DU24*$B33/12 -> 17655.367
A34: =A11 -> capex 8 | B34: =1/25 -> 0.04 | D34: =D25*$B34/12 -> 0 | E34: =E25*$B34/12 -> 0 | F34: =F25*$B34/12 -> 0 | G34: =G25*$B34/12 -> 0 | H34: =H25*$B34/12 -> 0 | I34: =I25*$B34/12 -> 6214.6893 | J34: =J25*$B34/12 -> 6214.6893 | K34: =K25*$B34/12 -> 6214.6893 | ... DU34: =DU25*$B34/12 -> 6214.6893
A35: =A12 -> capex 9 | B35: =1/10 -> 0.1 | D35: =D26*$B35/12 -> 0 | E35: =E26*$B35/12 -> 0 | F35: =F26*$B35/12 -> 0 | G35: =G26*$B35/12 -> 0 | H35: =H26*$B35/12 -> 0 | I35: =I26*$B35/12 -> 0 | J35: =J26*$B35/12 -> 0 | K35: =K26*$B35/12 -> 0 | ... DU35: =DU26*$B35/12 -> 3177.9661
A36: Остаточная стоимость | D36: =D17-D28 -> 0 | E36: =E17-SUM($D$28:E28) -> 0 | F36: =F17-SUM($D$28:F28) -> 0 | G36: =G17-SUM($D$28:G28) -> 0 | H36: =H17-SUM($D$28:H28) -> 0 | I36: =I17-SUM($D$28:I28) -> 4470477.4 | J36: =J17-SUM($D$28:J28) -> 4442310.7 | K36: =K17-SUM($D$28:K28) -> 4414144.1 | L36: =L17-SUM($D$28:L28) -> 4385977.4 | ... DU36: =DU17-SUM($D$28:DU28) -> 14073613
A37: Кредиторская задолженность по кап. затратам | D37: =-MIN(0,SUM($D$4:D5,$D$7:D7,$D$9:D12)/(1+vat)-D17) -> 0 | E37: =-MIN(0,SUM($D$4:E5,$D$7:E7,$D$9:E12)/(1+vat)-E17) -> 0 | F37: =-MIN(0,SUM($D$4:F5,$D$7:F7,$D$9:F12)/(1+vat)-F17) -> 0 | G37: =-MIN(0,SUM($D$4:G5,$D$7:G7,$D$9:G12)/(1+vat)-G17) -> 0 | H37: =-MIN(0,SUM($D$4:H5,$D$7:H7,$D$9:H12)/(1+vat)-H17) -> 0 | I37: =-MIN(0,SUM($D$4:I5,$D$7:I7,$D$9:I12)/(1+vat)-I17) -> 0 | J37: =-MIN(0,SUM($D$4:J5,$D$7:J7,$D$9:J12)/(1+vat)-J17) -> 0 | K37: =-MIN(0,SUM($D$4:K5,$D$7:K7,$D$9:K12)/(1+vat)-K17) -> 0 | ... DU37: =-MIN(0,SUM($D$4:DU5,$D$7:DU7,$D$9:DU12)/(1+vat)-DU17) -> 1.4901161e-08
A39: Выручка | C39: Сумма | D39: =D16 -> 41944 | E39: =E16 -> 41974 | F39: =F16 -> 42005 | G39: =G16 -> 42036 | H39: =H16 -> 42064 | I39: =I16 -> 42095 | J39: =J16 -> 42125 | K39: =K16 -> 42156 | ... DU39: =DU16 -> 45627
A40: Переработка сырья, т | B40: 50000 | C40: =SUM(D40:DU40) -> 5650000 | M40: =$B$40*volume -> 50000 | N40: =$B$40*volume -> 50000 | O40: =$B$40*volume -> 50000 | P40: =$B$40*volume -> 50000 | Q40: =$B$40*volume -> 50000 | R40: =$B$40*volume -> 50000 | S40: =$B$40*volume -> 50000 | T40: =$B$40*volume -> 50000 | ... DU40: =$B$40*volume -> 50000
A41: =СВОД!A7 -> сырье 1 | B41: =IF(var=1,СВОД!B7,СВОД!C7) -> 1 | C41: =SUM(D41:DU41) -> 5650000 | D41: =D$40*$B41 -> 0 | E41: =E$40*$B41 -> 0 | F41: =F$40*$B41 -> 0 | G41: =G$40*$B41 -> 0 | H41: =H$40*$B41 -> 0 | I41: =I$40*$B41 -> 0 | J41: =J$40*$B41 -> 0 | K41: =K$40*$B41 -> 0 | ... DU41: =DU$40*$B41 -> 50000
A42: =СВОД!A8 -> сырье 2 | B42: =1-B41 -> 0 | C42: =SUM(D42:DU42) -> 0 | D42: =D$40*$B42 -> 0 | E42: =E$40*$B42 -> 0 | F42: =F$40*$B42 -> 0 | G42: =G$40*$B42 -> 0 | H42: =H$40*$B42 -> 0 | I42: =I$40*$B42 -> 0 | J42: =J$40*$B42 -> 0 | K42: =K$40*$B42 -> 0 | ... DU42: =DU$40*$B42 -> 0
A43: Производство готовой продукции, т | B43: выход | C43: =SUM(D43:DU43) -> 5254500 | D43: =SUM(D44:D46) -> 0 | E43: =SUM(E44:E46) -> 0 | F43: =SUM(F44:F46) -> 0 | G43: =SUM(G44:G46) -> 0 | H43: =SUM(H44:H46) -> 0 | I43: =SUM(I44:I46) -> 0 | J43: =SUM(J44:J46) -> 0 | K43: =SUM(K44:K46) -> 0 | ... DU43: =SUM(DU44:DU46) -> 46500
A44: =СВОД!A10 -> продукт 1 | B44: =IF(var=1,СВОД!B10,СВОД!C10) -> 0.7 | C44: =SUM(D44:DU44) -> 3955000 | D44: =D$40*$B44 -> 0 | E44: =E$40*$B44 -> 0 | F44: =F$40*$B44 -> 0 | G44: =G$40*$B44 -> 0 | H44: =H$40*$B44 -> 0 | I44: =I$40*$B44 -> 0 | J44: =J$40*$B44 -> 0 | K44: =K$40*$B44 -> 0 | ... DU44: =DU$40*$B44 -> 35000
A45: =СВОД!A11 -> продукт 2 | B45: =IF(var=1,СВОД!B11,СВОД!C11) -> 0.23 | C45: =SUM(D45:DU45) -> 1299500 | D45: =D$40*$B45 -> 0 | E45: =E$40*$B45 -> 0 | F45: =F$40*$B45 -> 0 | G45: =G$40*$B45 -> 0 | H45: =H$40*$B45 -> 0 | I45: =I$40*$B45 -> 0 | J45: =J$40*$B45 -> 0 | K45: =K$40*$B45 -> 0 | ... DU45: =DU$40*$B45 -> 11500
...

Sheet кредит
A1: =title -> Вариант 1 | B1: http://exceltable.com/ | D1: 1 | E1: 2 | F1: 3 | G1: 4 | H1: 5 | I1: 6 | J1: 7 | K1: 8 | L1: 9 | M1: 10 | N1: 11 | O1: 12 | P1: 13 | Q1: 14 | R1: 15 | S1: 16 | T1: 17 | U1: 18 | V1: 19 | W1: 20 | X1: 21 | Y1: 22 | Z1: 23 | AA1: 24 | AB1: 25 | AC1: 26 | AD1: 27 | AE1: 28 | AF1: 29 | AG1: 30 | AH1: 31 | AI1: 32 | AJ1: 33 | AK1: 34 | AL1: 35 | AM1: 36 | AN1: 37 | AO1: 38 | AP1: 39 | AQ1: 40 | AR1: 41 | AS1: 42 | AT1: 43 | AU1: 44 | AV1: 45 | AW1: 46 | AX1: 47 | AY1: 48 | AZ1: 49 | BA1: 50 | BB1: 51 | BC1: 52 | BD1: 53 | BE1: 54 | BF1: 55 | BG1: 56 | BH1: 57 | BI1: 58 | BJ1: 59 | BK1: 60 | BL1: 61 | BM1: 62 | BN1: 63 | BO1: 64 | BP1: 65 | BQ1: 66 | BR1: 67 | BS1: 68 | BT1: 69 | BU1: 70 | BV1: 71 | BW1: 72 | BX1: 73 | BY1: 74 | BZ1: 75 | CA1: 76 | CB1: 77 | CC1: 78 | CD1: 79 | CE1: 80 | CF1: 81 | CG1: 82 | CH1: 83 | CI1: 84 | CJ1: 85 | CK1: 86 | CL1: 87 | CM1: 88 | CN1: 89 | CO1: 90 | CP1: 91 | CQ1: 92 | CR1: 93 | CS1: 94 | CT1: 95 | CU1: 96 | CV1: 97 | CW1: 98 | CX1: 99 | CY1: 100 | CZ1: 101 | DA1: 102 | DB1: 103 | DC1: 104 | DD1: 105 | DE1: 106 | DF1: 107 | DG1: 108 | DH1: 109 | DI1: 110 | DJ1: 111 | DK1: 112 | DL1: 113 | DM1: 114 | DN1: 115 | DO1: 116 | DP1: 117 | DQ1: 118 | DR1: 119 | DS1: 120 | DT1: 121 | DU1: 122
A2: =cur -> USD | D2: =YEAR(D3) -> 2014 | E2: =YEAR(E3) -> 2014 | F2: =YEAR(F3) -> 2015 | G2: =YEAR(G3) -> 2015 | H2: =YEAR(H3) -> 2015 | I2: =YEAR(I3) -> 2015 | J2: =YEAR(J3) -> 2015 | K2: =YEAR(K3) -> 2015 | ... DU2: =YEAR(DU3) -> 2024
A3: Кредит | C3: Сумма | D3: =данные!D3 -> 41944 | E3: =данные!E3 -> 41974 | F3: =данные!F3 -> 42005 | G3: =данные!G3 -> 42036 | H3: =данные!H3 -> 42064 | I3: =данные!I3 -> 42095 | J3: =данные!J3 -> 42125 | K3: =данные!K3 -> 42156 | ... DU3: =данные!DU3 -> 45627
A4: Получение | C4: =SUM(D4:DU4) -> 87100000 | D4: =-ROUNDUP((MIN(0,'Cash Flow'!D17+'Cash Flow'!D23-'Cash Flow'!D31))/100000,0)*100000+D16 -> 52300000 | E4: =-ROUNDUP((MIN(0,'Cash Flow'!D36+'Cash Flow'!E17+'Cash Flow'!E23-'Cash Flow'!E31))/100000,0)*100000+E16 -> 900000 | F4: =-ROUNDUP((MIN(0,'Cash Flow'!E36+'Cash Flow'!F17+'Cash Flow'!F23-'Cash Flow'!F31))/100000,0)*100000+F16 -> 1100000 | G4: =-ROUNDUP((MIN(0,'Cash Flow'!F36+'Cash Flow'!G17+'Cash Flow'!G23-'Cash Flow'!G31))/100000,0)*100000+G16 -> 900000 | H4: =-ROUNDUP((MIN(0,'Cash Flow'!G36+'Cash Flow'!H17+'Cash Flow'!H23-'Cash Flow'!H31))/100000,0)*100000+H16 -> 2200000 | I4: =-ROUNDUP((MIN(0,'Cash Flow'!H36+'Cash Flow'!I17+'Cash Flow'!I23-'Cash Flow'!I31))/100000,0)*100000+I16 -> 1600000 | J4: =-ROUNDUP((MIN(0,'Cash Flow'!I36+'Cash Flow'!J17+'Cash Flow'!J23-'Cash Flow'!J31))/100000,0)*100000+J16 -> 1100000 | K4: =-ROUNDUP((MIN(0,'Cash Flow'!J36+'Cash Flow'!K17+'Cash Flow'!K23-'Cash Flow'!K31))/100000,0)*100000+K16 -> 1500000 | L4: =-ROUNDUP((MIN(0,'Cash Flow'!K36+'Cash Flow'!L17+'Cash Flow'!L23-'Cash Flow'!L31))/100000,0)*100000+L16 -> 17400000 | M4: =-ROUNDUP((MIN(0,'Cash Flow'!L36+'Cash Flow'!M17+'Cash Flow'!M23-'Cash Flow'!M31))/100000,0)*100000+M16 -> 8100000
A5: Льготный период, мес. | B5: 12
A6: Срок, мес. | B6: =IF(var=1,СВОД!B19,СВОД!C19) -> 18
A7: Погашение | C7: =SUM(D7:BK7) -> 87100000 | E7: =IF(AND(E1>$B$5,E1<=$B$6+1),$C$4/($B$6-$B$5+1),0) -> 0 | F7: =IF(AND(F1>$B$5,F1<=$B$6+1),$C$4/($B$6-$B$5+1),0) -> 0 | G7: =IF(AND(G1>$B$5,G1<=$B$6+1),$C$4/($B$6-$B$5+1),0) -> 0 | H7: =IF(AND(H1>$B$5,H1<=$B$6+1),$C$4/($B$6-$B$5+1),0) -> 0 | I7: =IF(AND(I1>$B$5,I1<=$B$6+1),$C$4/($B$6-$B$5+1),0) -> 0 | J7: =IF(AND(J1>$B$5,J1<=$B$6+1),$C$4/($B$6-$B$5+1),0) -> 0 | K7: =IF(AND(K1>$B$5,K1<=$B$6+1),$C$4/($B$6-$B$5+1),0) -> 0 | L7: =IF(AND(L1>$B$5,L1<=$B$6+1),$C$4/($B$6-$B$5+1),0) -> 0 | ... DU7: =IF(AND(DU1>$B$5,DU1<=$B$6+1),$C$4/($B$6-$B$5+1),0) -> 0
A8: Проценты
A9: начисленные | C9: =SUM(D9:BK9) -> 5885833.3 | E9: =IF(E1<=$B$5,D11*$B$10/12,0) -> 435833.33 | F9: =IF(F1<=$B$5,E11*$B$10/12,0) -> 443333.33 | G9: =IF(G1<=$B$5,F11*$B$10/12,0) -> 452500 | H9: =IF(H1<=$B$5,G11*$B$10/12,0) -> 460000 | I9: =IF(I1<=$B$5,H11*$B$10/12,0) -> 478333.33 | J9: =IF(J1<=$B$5,I11*$B$10/12,0) -> 491666.67 | K9: =IF(K1<=$B$5,J11*$B$10/12,0) -> 500833.33 | L9: =IF(L1<=$B$5,K11*$B$10/12,0) -> 513333.33 | ... DU9: =IF(DU1<=$B$5,DT11*$B$10/12,0) -> 0
A10: выплаченные | B10: 0.1 | C10: =SUM(D10:BK10) -> 8789166.7 | E10: =IF(E1>$B$5,D11*$B$10/12,0)+IF(E1=$B$5+1,SUM($D$9:E9),0) -> 0 | F10: =IF(F1>$B$5,E11*$B$10/12,0)+IF(F1=$B$5+1,SUM($D$9:F9),0) -> 0 | G10: =IF(G1>$B$5,F11*$B$10/12,0)+IF(G1=$B$5+1,SUM($D$9:G9),0) -> 0 | H10: =IF(H1>$B$5,G11*$B$10/12,0)+IF(H1=$B$5+1,SUM($D$9:H9),0) -> 0 | I10: =IF(I1>$B$5,H11*$B$10/12,0)+IF(I1=$B$5+1,SUM($D$9:I9),0) -> 0 | J10: =IF(J1>$B$5,I11*$B$10/12,0)+IF(J1=$B$5+1,SUM($D$9:J9),0) -> 0 | K10: =IF(K1>$B$5,J11*$B$10/12,0)+IF(K1=$B$5+1,SUM($D$9:K9),0) -> 0 | L10: =IF(L1>$B$5,K11*$B$10/12,0)+IF(L1=$B$5+1,SUM($D$9:L9),0) -> 0 | ... DU10: =IF(DU1>$B$5,DT11*$B$10/12,0)+IF(DU1=$B$5+1,SUM($D$9:DU9),0) -> 0
A11: Остаток долга | C11: =BK11 -> 0 | D11: =D4-D7 -> 52300000 | E11: =D11+E4-E7 -> 53200000 | F11: =E11+F4-F7 -> 54300000 | G11: =F11+G4-G7 -> 55200000 | H11: =G11+H4-H7 -> 57400000 | I11: =H11+I4-I7 -> 59000000 | J11: =I11+J4-J7 -> 60100000 | K11: =J11+K4-K7 -> 61600000 | L11: =K11+L4-L7 -> 79000000 | ... DU11: =DT11+DU4-DU7 -> 0
A14: Резерв, вариант 1 | D14: 1000000 | E14: 800000 | F14: 800000 | G14: 700000 | H14: 1200000 | I14: 1300000 | J14: 900000 | K14: 900000 | L14: 1400000
A15: Резерв, вариант 2 | D15: 1000000 | E15: 800000 | F15: 800000 | G15: 700000 | H15: 1200000 | I15: 1300000 | J15: 900000 | K15: 900000 | L15: 6500000
D16: =IF(var=1,D14,D15) -> 1000000 | E16: =IF(var=1,E14,E15) -> 800000 | F16: =IF(var=1,F14,F15) -> 800000 | G16: =IF(var=1,G14,G15) -> 700000 | H16: =IF(var=1,H14,H15) -> 1200000 | I16: =IF(var=1,I14,I15) -> 1300000 | J16: =IF(var=1,J14,J15) -> 900000 | K16: =IF(var=1,K14,K15) -> 900000 | ... DM16: =IF(var=1,DM14,DM15) -> 0

Sheet Cash Flow
A1: =title -> Вариант 1 | C1: http://exceltable.com/ | D1: 1 | E1: 2 | F1: 3 | G1: 4 | H1: 5 | I1: 6 | J1: 7 | K1: 8 | L1: 9 | M1: 10 | N1: 11 | O1: 12 | P1: 13 | Q1: 14 | R1: 15 | S1: 16 | T1: 17 | U1: 18 | V1: 19 | W1: 20 | X1: 21 | Y1: 22 | Z1: 23 | AA1: 24 | AB1: 25 | AC1: 26 | AD1: 27 | AE1: 28 | AF1: 29 | AG1: 30 | AH1: 31 | AI1: 32 | AJ1: 33 | AK1: 34 | AL1: 35 | AM1: 36 | AN1: 37 | AO1: 38 | AP1: 39 | AQ1: 40 | AR1: 41 | AS1: 42 | AT1: 43 | AU1: 44 | AV1: 45 | AW1: 46 | AX1: 47 | AY1: 48 | AZ1: 49 | BA1: 50 | BB1: 51 | BC1: 52 | BD1: 53 | BE1: 54 | BF1: 55 | BG1: 56 | BH1: 57 | BI1: 58 | BJ1: 59 | BK1: 60 | BL1: 61 | BM1: 62 | BN1: 63 | BO1: 64 | BP1: 65 | BQ1: 66 | BR1: 67 | BS1: 68 | BT1: 69 | BU1: 70 | BV1: 71 | BW1: 72 | BX1: 73 | BY1: 74 | BZ1: 75 | CA1: 76 | CB1: 77 | CC1: 78 | CD1: 79 | CE1: 80 | CF1: 81 | CG1: 82 | CH1: 83 | CI1: 84 | CJ1: 85 | CK1: 86 | CL1: 87 | CM1: 88 | CN1: 89 | CO1: 90 | CP1: 91 | CQ1: 92 | CR1: 93 | CS1: 94 | CT1: 95 | CU1: 96 | CV1: 97 | CW1: 98 | CX1: 99 | CY1: 100 | CZ1: 101 | DA1: 102 | DB1: 103 | DC1: 104 | DD1: 105 | DE1: 106 | DF1: 107 | DG1: 108 | DH1: 109 | DI1: 110 | DJ1: 111 | DK1: 112 | DL1: 113 | DM1: 114 | DN1: 115 | DO1: 116 | DP1: 117 | DQ1: 118 | DR1: 119 | DS1: 120 | DT1: 121 | DU1: 122
A2: =cur -> USD | D2: =YEAR(D3) -> 2014 | E2: =YEAR(E3) -> 2014 | F2: =YEAR(F3) -> 2015 | G2: =YEAR(G3) -> 2015 | H2: =YEAR(H3) -> 2015 | I2: =YEAR(I3) -> 2015 | J2: =YEAR(J3) -> 2015 | K2: =YEAR(K3) -> 2015 | ... DU2: =YEAR(DU3) -> 2024
A3: Движение денежных средств | C3: Сумма | D3: =данные!D3 -> 41944 | E3: =данные!E3 -> 41974 | F3: =данные!F3 -> 42005 | G3: =данные!G3 -> 42036 | H3: =данные!H3 -> 42064 | I3: =данные!I3 -> 42095 | J3: =данные!J3 -> 42125 | K3: =данные!K3 -> 42156 | ... DU3: =данные!DU3 -> 45627
A4: 1. Основная деятельность
A5: Выручка от реализации | C5: =SUM(D5:DU5) -> 6.5009942e+09 | D5: =данные!D51-данные!D156 -> 0 | E5: =данные!E51-данные!E156 -> 0 | F5: =данные!F51-данные!F156 -> 0 | G5: =данные!G51-данные!G156 -> 0 | H5: =данные!H51-данные!H156 -> 0 | I5: =данные!I51-данные!I156 -> 0 | J5: =данные!J51-данные!J156 -> 0 | K5: =данные!K51-данные!K156 -> 0 | ... DU5: =данные!DU51-данные!DU156 -> 72933757
A6: Прямые расходы | C6: =SUM(D6:DU6) -> 4.4710084e+09 | D6: =D7+D8 -> 0 | E6: =E7+E8 -> 0 | F6: =F7+F8 -> 0 | G6: =G7+G8 -> 0 | H6: =H7+H8 -> 0 | I6: =I7+I8 -> 0 | J6: =J7+J8 -> 0 | K6: =K7+K8 -> 0 | ... DU6: =DU7+DU8 -> 49666839
A7: сырье | C7: =SUM(D7:DU7) -> 4.3802084e+09 | D7: =данные!D67 -> 0 | E7: =данные!E67 -> 0 | F7: =данные!F67 -> 0 | G7: =данные!G67 -> 0 | H7: =данные!H67 -> 0 | I7: =данные!I67 -> 0 | J7: =данные!J67 -> 0 | K7: =данные!K67 -> 0 | ... DU7: =данные!DU67 -> 48866839
A8: энергия | C8: =SUM(D8:DU8) -> 90800000 | D8: =данные!D77 -> 0 | E8: =данные!E77 -> 0 | F8: =данные!F77 -> 0 | G8: =данные!G77 -> 0 | H8: =данные!H77 -> 0 | I8: =данные!I77 -> 0 | J8: =данные!J77 -> 0 | K8: =данные!K77 -> 0 | ... DU8: =данные!DU77 -> 800000
A9: Постоянные расходы | C9: =SUM(D9:DU9) -> 85590747 | D9: =SUM(D10:D11) -> 0 | E9: =SUM(E10:E11) -> 0 | F9: =SUM(F10:F11) -> 0 | G9: =SUM(G10:G11) -> 0 | H9: =SUM(H10:H11) -> 0 | I9: =SUM(I10:I11) -> 0 | J9: =SUM(J10:J11) -> 0 | K9: =SUM(K10:K11) -> 0 | ... DU9: =SUM(DU10:DU11) -> 713584
A10: ФОТ | C10: =SUM(D10:DU10) -> 40377913 | D10: =данные!D118-данные!D165 -> 0 | E10: =данные!E118-(данные!E165-данные!D165) -> 0 | F10: =данные!F118-(данные!F165-данные!E165) -> 0 | G10: =данные!G118-(данные!G165-данные!F165) -> 0 | H10: =данные!H118-(данные!H165-данные!G165) -> 0 | I10: =данные!I118-(данные!I165-данные!H165) -> 0 | J10: =данные!J118-(данные!J165-данные!I165) -> 0 | K10: =данные!K118-(данные!K165-данные!J165) -> 0 | L10: =данные!L118-(данные!L165-данные!K165) -> 0 | ... DU10: =данные!DU118-(данные!DU165-данные!DT165) -> 387417.33
A11: общие издержки | C11: =SUM(D11:DU11) -> 45212833 | D11: =данные!D96-данные!D164 -> 0 | E11: =данные!E96-(данные!E164-данные!E164) -> 0 | F11: =данные!F96-(данные!F164-данные!F164) -> 0 | G11: =данные!G96-(данные!G164-данные!G164) -> 0 | H11: =данные!H96-(данные!H164-данные!H164) -> 0 | I11: =данные!I96-(данные!I164-данные!I164) -> 0 | J11: =данные!J96-(данные!J164-данные!J164) -> 0 | K11: =данные!K96-(данные!K164-данные!K164) -> 0 | L11: =данные!L96-(данные!L164-данные!L164) -> 0 | ... DU11: =данные!DU96-(данные!DU164-данные!DU164) -> 326166.67
A12: Суммарные издержки производства | C12: =SUM(D12:DU12) -> 4.5565992e+09 | D12: =SUM(D6,D9) -> 0 | E12: =SUM(E6,E9) -> 0 | F12: =SUM(F6,F9) -> 0 | G12: =SUM(G6,G9) -> 0 | H12: =SUM(H6,H9) -> 0 | I12: =SUM(I6,I9) -> 0 | J12: =SUM(J6,J9) -> 0 | K12: =SUM(K6,K9) -> 0 | ... DU12: =SUM(DU6,DU9) -> 50380423
A13: Налоги | C13: =SUM(D13:DU13) -> 6.1672746e+08 | D13: =SUM(D14:D16) -> 0 | E13: =SUM(E14:E16) -> 0 | F13: =SUM(F14:F16) -> 0 | G13: =SUM(G14:G16) -> 0 | H13: =SUM(H14:H16) -> 0 | I13: =SUM(I14:I16) -> 0 | J13: =SUM(J14:J16) -> 0 | K13: =SUM(K14:K16) -> 0 | ... DU13: =SUM(DU14:DU16) -> 7212198.2
A14: НДС | C14: =SUM(D14:DU14) -> 2.9022479e+08 | D14: =данные!D144-данные!D166 -> 0 | E14: =данные!E144-(данные!E166-данные!D166) -> 0 | F14: =данные!F144-(данные!F166-данные!E166) -> 0 | G14: =данные!G144-(данные!G166-данные!F166) -> 0 | H14: =данные!H144-(данные!H166-данные!G166) -> 0 | I14: =данные!I144-(данные!I166-данные!H166) -> 0 | J14: =данные!J144-(данные!J166-данные!I166) -> 0 | K14: =данные!K144-(данные!K166-данные!J166) -> 0 | L14: =данные!L144-(данные!L166-данные!K166) -> 0 | ... DU14: =данные!DU144-(данные!DU166-данные!DT166) -> 3499436.7
A15: Налог на имущество | C15: =SUM(D15:DU15) -> 8550389.4 | D15: =данные!D150 -> 0 | E15: =данные!E150 -> 0 | F15: =данные!F150 -> 0 | G15: =данные!G150 -> 0 | H15: =данные!H150 -> 0 | I15: =данные!I150 -> 0 | J15: =данные!J150 -> 0 | K15: =данные!K150 -> 0 | ... DU15: =данные!DU150 -> 0
A16: Налог на прибыль | C16: =SUM(D16:DU16) -> 3.1795227e+08 | D16: =PL!D18-данные!D167 -> 0 | E16: =PL!E18-(данные!E167-данные!D167) -> 0 | F16: =PL!F18-(данные!F167-данные!E167) -> 0 | G16: =PL!G18-(данные!G167-данные!F167) -> 0 | H16: =PL!H18-(данные!H167-данные!G167) -> 0 | I16: =PL!I18-(данные!I167-данные!H167) -> 0 | J16: =PL!J18-(данные!J167-данные!I167) -> 0 | K16: =PL!K18-(данные!K167-данные!J167) -> 0 | L16: =PL!L18-(данные!L167-данные!K167) -> 0 | ... DU16: =PL!DU18-(данные!DU167-данные!DT167) -> 3712761.5
A17: Итого кэш-фло по основной деятельности | C17: =SUM(D17:DU17) -> 1.3276676e+09 | D17: =D5-D12-D13 -> 0 | E17: =E5-E12-E13 -> 0 | F17: =F5-F12-F13 -> 0 | G17: =G5-G12-G13 -> 0 | H17: =H5-H12-H13 -> 0 | I17: =I5-I12-I13 -> 0 | J17: =J5-J12-J13 -> 0 | K17: =K5-K12-K13 -> 0 | ... DU17: =DU5-DU12-DU13 -> 15341136
A19: 2. Инвестиционная деятельность
A20: Реализация основных средств | C20: =SUM(D20:DU20) -> 0 | G20: 0 | H20: 0 | I20: 0 | J20: 0 | K20: 0 | L20: 0 | M20: 0 | N20: 0 | O20: 0 | P20: 0 | Q20: 0 | R20: 0 | S20: 0 | T20: 0 | U20: 0 | V20: 0 | W20: 0 | X20: 0 | Y20: 0 | Z20: 0 | AA20: 0 | AB20: 0 | AC20: 0 | AD20: 0 | AE20: 0 | AF20: 0 | AG20: 0 | AH20: 0 | AI20: 0 | AJ20: 0 | AK20: 0 | AL20: 0 | AM20: 0 | AN20: 0 | AO20: 0 | AP20: 0 | AQ20: 0 | AR20: 0 | AS20: 0 | AT20: 0 | AU20: 0 | AV20: 0 | AW20: 0 | AX20: 0 | AY20: 0 | AZ20: 0 | BA20: 0 | BB20: 0 | BC20: 0 | BD20: 0 | BE20: 0 | BF20: 0 | BG20: 0 | BH20: 0 | BI20: 0 | BJ20: 0 | BK20: 0 | BL20: 0 | BM20: 0 | BN20: 0 | BO20: 0 | BP20: 0 | BQ20: 0 | BR20: 0 | BS20: 0 | BT20: 0 | BU20: 0 | BV20: 0 | BW20: 0 | BX20: 0 | BY20: 0 | BZ20: 0 | CA20: 0 | CB20: 0 | CC20: 0 | CD20: 0 | CE20: 0 | CF20: 0 | CG20: 0 | CH20: 0 | CI20: 0 | CJ20: 0 | CK20: 0 | CL20: 0 | CM20: 0 | CN20: 0 | CO20: 0 | CP20: 0 | CQ20: 0 | CR20: 0 | CS20: 0 | CT20: 0 | CU20: 0 | CV20: 0 | CW20: 0 | CX20: 0 | CY20: 0 | CZ20: 0 | DA20: 0 | DB20: 0 | DC20: 0 | DD20: 0 | DE20: 0 | DF20: 0 | DG20: 0 | DH20: 0 | DI20: 0 | DJ20: 0 | DK20: 0 | DL20: 0 | DM20: 0 | DN20: 0 | DO20: 0 | DP20: 0 | DQ20: 0 | DR20: 0 | DS20: 0 | DT20: 0 | DU20: 0
A21: Затраты на приобретение активов | C21: =SUM(D21:DU21) -> 82088400 | D21: =SUM(данные!D4:D5,данные!D7,данные!D9:D12)*capex -> 51197900 | E21: =SUM(данные!E4:E5,данные!E7,данные!E9:E12)*capex -> 1065000 | F21: =SUM(данные!F4:F5,данные!F7,данные!F9:F12)*capex -> 1065000 | G21: =SUM(данные!G4:G5,данные!G7,данные!G9:G12)*capex -> 1065000 | H21: =SUM(данные!H4:H5,данные!H7,данные!H9:H12)*capex -> 1670500 | I21: =SUM(данные!I4:I5,данные!I7,данные!I9:I12)*capex -> 1495000 | J21: =SUM(данные!J4:J5,данные!J7,данные!J9:J12)*capex -> 1495000 | K21: =SUM(данные!K4:K5,данные!K7,данные!K9:K12)*capex -> 1495000 | ... DU21: =SUM(данные!DU4:DU5,данные!DU7,данные!DU9:DU12)*capex -> 0
A22: Прочие расходы подготовительного периода | C22: =SUM(D22:DU22) -> 99780 | D22: =SUM(данные!D6,данные!D8) -> 99780 | E22: =SUM(данные!E6,данные!E8) -> 0 | F22: =SUM(данные!F6,данные!F8) -> 0 | G22: =SUM(данные!G6,данные!G8) -> 0 | H22: =SUM(данные!H6,данные!H8) -> 0 | I22: =SUM(данные!I6,данные!I8) -> 0 | J22: =SUM(данные!J6,данные!J8) -> 0 | K22: =SUM(данные!K6,данные!K8) -> 0 | ... DU22: =SUM(данные!DU6,данные!DU8) -> 0
A23: Итого кэш-фло по инвест. деятельности | C23: =SUM(D23:DU23) -> -82188180 | D23: =D20-D21-D22 -> -51297680 | E23: =E20-E21-E22 -> -1065000 | F23: =F20-F21-F22 -> -1065000 | G23: =G20-G21-G22 -> -1065000 | H23: =H20-H21-H22 -> -1670500 | I23: =I20-I21-I22 -> -1495000 | J23: =J20-J21-J22 -> -1495000 | K23: =K20-K21-K22 -> -1495000 | ... DU23: =DU20-DU21-DU22 -> 0
A25: 3. Финансовая деятельность
A26: Собственный капитал | C26: =SUM(D26:DU26) -> 0 | D26: 0 | E26: 0 | F26: 0 | G26: 0 | H26: 0 | I26: 0 | J26: 0 | K26: 0 | L26: 0 | M26: 0 | N26: 0 | O26: 0 | P26: 0 | Q26: 0 | R26: 0 | S26: 0 | T26: 0 | U26: 0 | V26: 0 | W26: 0 | X26: 0 | Y26: 0 | Z26: 0 | AA26: 0 | AB26: 0 | AC26: 0 | AD26: 0 | AE26: 0 | AF26: 0 | AG26: 0 | AH26: 0 | AI26: 0 | AJ26: 0 | AK26: 0 | AL26: 0 | AM26: 0 | AN26: 0 | AO26: 0 | AP26: 0 | AQ26: 0 | AR26: 0 | AS26: 0 | AT26: 0 | AU26: 0 | AV26: 0 | AW26: 0 | AX26: 0 | AY26: 0 | AZ26: 0 | BA26: 0 | BB26: 0 | BC26: 0 | BD26: 0 | BE26: 0 | BF26: 0 | BG26: 0 | BH26: 0 | BI26: 0 | BJ26: 0 | BK26: 0 | BL26: 0 | BM26: 0 | BN26: 0 | BO26: 0 | BP26: 0 | BQ26: 0 | BR26: 0 | BS26: 0 | BT26: 0 | BU26: 0 | BV26: 0 | BW26: 0 | BX26: 0 | BY26: 0 | BZ26: 0 | CA26: 0 | CB26: 0 | CC26: 0 | CD26: 0 | CE26: 0 | CF26: 0 | CG26: 0 | CH26: 0 | CI26: 0 | CJ26: 0 | CK26: 0 | CL26: 0 | CM26: 0 | CN26: 0 | CO26: 0 | CP26: 0 | CQ26: 0 | CR26: 0 | CS26: 0 | CT26: 0 | CU26: 0 | CV26: 0 | CW26: 0 | CX26: 0 | CY26: 0 | CZ26: 0 | DA26: 0 | DB26: 0 | DC26: 0 | DD26: 0 | DE26: 0 | DF26: 0 | DG26: 0 | DH26: 0 | DI26: 0 | DJ26: 0 | DK26: 0 | DL26: 0 | DM26: 0 | DN26: 0 | DO26: 0 | DP26: 0 | DQ26: 0 | DR26: 0 | DS26: 0 | DT26: 0 | DU26: 0
C27: =SUM(D27:DU27) -> 0
A28: Получение кредита | C28: =SUM(D28:DU28) -> 87100000 | D28: =кредит!D4 -> 52300000 | E28: =кредит!E4 -> 900000 | F28: =кредит!F4 -> 1100000 | G28: =кредит!G4 -> 900000 | H28: =кредит!H4 -> 2200000 | I28: =кредит!I4 -> 1600000 | J28: =кредит!J4 -> 1100000 | K28: =кредит!K4 -> 1500000 | ... DU28: =кредит!DU4 -> 0
A29: Платежи по кредиту | C29: =SUM(D29:DU29) -> 95889167 | D29: =D30+D31 -> 0 | E29: =E30+E31 -> 0 | F29: =F30+F31 -> 0 | G29: =G30+G31 -> 0 | H29: =H30+H31 -> 0 | I29: =I30+I31 -> 0 | J29: =J30+J31 -> 0 | K29: =K30+K31 -> 0 | ... DU29: =DU30+DU31 -> 0
A30: Погашение долга | C30: =SUM(D30:DU30) -> 87100000 | D30: =кредит!D7 -> 0 | E30: =кредит!E7 -> 0 | F30: =кредит!F7 -> 0 | G30: =кредит!G7 -> 0 | H30: =кредит!H7 -> 0 | I30: =кредит!I7 -> 0 | J30: =кредит!J7 -> 0 | K30: =кредит!K7 -> 0 | ... DU30: =кредит!DU7 -> 0
A31: Проценты | C31: =SUM(D31:DU31) -> 8789166.7 | D31: =кредит!D10 -> 0 | E31: =кредит!E10 -> 0 | F31: =кредит!F10 -> 0 | G31: =кредит!G10 -> 0 | H31: =кредит!H10 -> 0 | I31: =кредит!I10 -> 0 | J31: =кредит!J10 -> 0 | K31: =кредит!K10 -> 0 | ... DU31: =кредит!DU10 -> 0
C32: =SUM(D32:DU32) -> 0
A33: Итого кэш-фло по финансовой деятельности | C33: =SUM(D33:DU33) -> -8789166.7 | D33: =D26+D28-D29 -> 52300000 | E33: =E26+E28-E29 -> 900000 | F33: =F26+F28-F29 -> 1100000 | G33: =G26+G28-G29 -> 900000 | H33: =H26+H28-H29 -> 2200000 | I33: =I26+I28-I29 -> 1600000 | J33: =J26+J28-J29 -> 1100000 | K33: =K26+K28-K29 -> 1500000 | ... DU33: =DU26+DU28-DU29 -> 0
A35: Итого поток денежных средств | C35: =SUM(D35:DU35) -> 1.2366902e+09 | D35: =D17+D23+D33 -> 1002320 | E35: =E17+E23+E33 -> -165000 | F35: =F17+F23+F33 -> 35000 | G35: =G17+G23+G33 -> -165000 | H35: =H17+H23+H33 -> 529500 | I35: =I17+I23+I33 -> 105000 | J35: =J17+J23+J33 -> -395000 | K35: =K17+K23+K33 -> 5000 | ... DU35: =DU17+DU23+DU33 -> 15341136
A36: Баланс денежных средств на конец периода | C36: =DU36 -> 1.2366902e+09 | D36: =D35 -> 1002320 | E36: =D36+E35 -> 837320 | F36: =E36+F35 -> 872320 | G36: =F36+G35 -> 707320 | H36: =G36+H35 -> 1236820 | I36: =H36+I35 -> 1341820 | J36: =I36+J35 -> 946820 | K36: =J36+K35 -> 951820 | L36: =K36+L35 -> 1438495.5 | ... DU36: =DT36+DU35 -> 1.2366902e+09
A39: Движение денежных средств | C39: Сумма | D39: =D3 -> 41944 | E39: =E3 -> 41974 | F39: =F3 -> 42005 | G39: =G3 -> 42036 | H39: =H3 -> 42064 | I39: =I3 -> 42095 | J39: =J3 -> 42125 | K39: =K3 -> 42156 | ... DU39: =DU3 -> 45627
A40: Чистая прибыль | C40: =SUM(D40:DU40) -> 1.2718091e+09 | D40: =PL!D19 -> -84559.322 | E40: =PL!E19 -> 0 | F40: =PL!F19 -> 0 | G40: =PL!G19 -> 0 | H40: =PL!H19 -> 0 | I40: =PL!I19 -> -28166.667 | J40: =PL!J19 -> -28166.667 | K40: =PL!K19 -> -28166.667 | ... DU40: =PL!DU19 -> 14851046
A41: Амортизация | C41: =SUM(D41:DU41) -> 55492828 | D41: =PL!D14 -> 0 | E41: =PL!E14 -> 0 | F41: =PL!F14 -> 0 | G41: =PL!G14 -> 0 | H41: =PL!H14 -> 0 | I41: =PL!I14 -> 28166.667 | J41: =PL!J14 -> 28166.667 | K41: =PL!K14 -> 28166.667 | ... DU41: =PL!DU14 -> 490089.92
A42: Изменение оборотного капитала | C42: =SUM(D42:DU42) -> -21045271 | D42: =BS!D10 -> 0 | E42: =-(BS!E10-BS!D10) -> 0 | F42: =-(BS!F10-BS!E10) -> 0 | G42: =-(BS!G10-BS!F10) -> 0 | H42: =-(BS!H10-BS!G10) -> 0 | I42: =-(BS!I10-BS!H10) -> 0 | J42: =-(BS!J10-BS!I10) -> 0 | K42: =-(BS!K10-BS!J10) -> 0 | L42: =-(BS!L10-BS!K10) -> -13050847 | ... DU42: =-(BS!DU10-BS!DT10) -> -4.7683716e-07
A43: НДС по приобретенным ценностям | C43: =SUM(D43:DU43) -> 0 | D43: =-(BS!D12-BS!C12) -> -7825069.8 | E43: =-(BS!E12-BS!D12) -> -162457.63 | F43: =-(BS!F12-BS!E12) -> -162457.63 | G43: =-(BS!G12-BS!F12) -> -162457.63 | H43: =-(BS!H12-BS!G12) -> -254822.03 | I43: =-(BS!I12-BS!H12) -> -228050.85 | J43: =-(BS!J12-BS!I12) -> -228050.85 | K43: =-(BS!K12-BS!J12) -> -228050.85 | ... DU43: =-(BS!DU12-BS!DT12) -> 0
A44: Поток д/с от операций | C44: =SUM(D44:DU44) -> 1.3062567e+09 | D44: =D40+D41+D42+D43 -> -7909629.2 | E44: =E40+E41+E42+E43 -> -162457.63 | F44: =F40+F41+F42+F43 -> -162457.63 | G44: =G40+G41+G42+G43 -> -162457.63 | H44: =H40+H41+H42+H43 -> -254822.03 | I44: =I40+I41+I42+I43 -> -228050.85 | J44: =J40+J41+J42+J43 -> -228050.85 | K44: =K40+K41+K42+K43 -> -228050.85 | ... DU44: =DU40+DU41+DU42+DU43 -> 15341136
A45: Поток д/с от инвестиц. деятельности | C45: =SUM(D45:DU45) -> -69566441 | D45: =-(SUM(данные!D4:D5,данные!D7,данные!D9:D12)/(1+vat)) -> -43388051 | E45: =-(SUM(данные!E4:E5,данные!E7,данные!E9:E12)/(1+vat)) -> -902542.37 | F45: =-(SUM(данные!F4:F5,данные!F7,данные!F9:F12)/(1+vat)) -> -902542.37 | G45: =-(SUM(данные!G4:G5,данные!G7,данные!G9:G12)/(1+vat)) -> -902542.37 | H45: =-(SUM(данные!H4:H5,данные!H7,данные!H9:H12)/(1+vat)) -> -1415678 | I45: =-(SUM(данные!I4:I5,данные!I7,данные!I9:I12)/(1+vat)) -> -1266949.2 | J45: =-(SUM(данные!J4:J5,данные!J7,данные!J9:J12)/(1+vat)) -> -1266949.2 | K45: =-(SUM(данные!K4:K5,данные!K7,данные!K9:K12)/(1+vat)) -> -1266949.2 | ... DU45: =-(SUM(данные!DU4:DU5,данные!DU7,данные!DU9:DU12)/(1+vat)) -> 0
...

Sheet PL
A1: =title -> Вариант 1 | C1: http://exceltable.com/ | D1: 1 | E1: 2 | F1: 3 | G1: 4 | H1: 5 | I1: 6 | J1: 7 | K1: 8 | L1: 9 | M1: 10 | N1: 11 | O1: 12 | P1: 13 | Q1: 14 | R1: 15 | S1: 16 | T1: 17 | U1: 18 | V1: 19 | W1: 20 | X1: 21 | Y1: 22 | Z1: 23 | AA1: 24 | AB1: 25 | AC1: 26 | AD1: 27 | AE1: 28 | AF1: 29 | AG1: 30 | AH1: 31 | AI1: 32 | AJ1: 33 | AK1: 34 | AL1: 35 | AM1: 36 | AN1: 37 | AO1: 38 | AP1: 39 | AQ1: 40 | AR1: 41 | AS1: 42 | AT1: 43 | AU1: 44 | AV1: 45 | AW1: 46 | AX1: 47 | AY1: 48
A2: =cur -> USD | D2: =YEAR(D3) -> 2014 | E2: =YEAR(E3) -> 2014 | F2: =YEAR(F3) -> 2015 | G2: =YEAR(G3) -> 2015 | H2: =YEAR(H3) -> 2015 | I2: =YEAR(I3) -> 2015 | J2: =YEAR(J3) -> 2015 | K2: =YEAR(K3) -> 2015 | ... DU2: =YEAR(DU3) -> 2024
A3: Прибыли/убытки | C3: Сумма | D3: =данные!D147 -> 41944 | E3: =данные!E147 -> 41974 | F3: =данные!F147 -> 42005 | G3: =данные!G147 -> 42036 | H3: =данные!H147 -> 42064 | I3: =данные!I147 -> 42095 | J3: =данные!J147 -> 42125 | K3: =данные!K147 -> 42156 | ... DU3: =данные!DU147 -> 45627
A4: Выручка от реализации (без НДС) | C4: =SUM(D4:DU4) -> 5.5093171e+09 | D4: =данные!D56 -> 0 | E4: =данные!E56 -> 0 | F4: =данные!F56 -> 0 | G4: =данные!G56 -> 0 | H4: =данные!H56 -> 0 | I4: =данные!I56 -> 0 | J4: =данные!J56 -> 0 | K4: =данные!K56 -> 0 | ... DU4: =данные!DU56 -> 61808269
A5: Прямые расходы (без НДС) | C5: =SUM(D5:DU5) -> 3.7679449e+09 | D5: =данные!D63/(1+vat)+данные!D75 -> 0 | E5: =данные!E63/(1+vat)+данные!E75 -> 0 | F5: =данные!F63/(1+vat)+данные!F75 -> 0 | G5: =данные!G63/(1+vat)+данные!G75 -> 0 | H5: =данные!H63/(1+vat)+данные!H75 -> 0 | I5: =данные!I63/(1+vat)+данные!I75 -> 0 | J5: =данные!J63/(1+vat)+данные!J75 -> 0 | K5: =данные!K63/(1+vat)+данные!K75 -> 0 | ... DU5: =данные!DU63/(1+vat)+данные!DU75 -> 42090541
A6: Валовая прибыль | C6: =SUM(D6:DU6) -> 1.7413722e+09 | D6: =D4-D5 -> 0 | E6: =E4-E5 -> 0 | F6: =F4-F5 -> 0 | G6: =G4-G5 -> 0 | H6: =H4-H5 -> 0 | I6: =I4-I5 -> 0 | J6: =J4-J5 -> 0 | K6: =K4-K5 -> 0 | ... DU6: =DU4-DU5 -> 19717727
A7: ФОТ | C7: =SUM(D7:DU7) -> 40377913 | D7: =данные!D118 -> 0 | E7: =данные!E118 -> 0 | F7: =данные!F118 -> 0 | G7: =данные!G118 -> 0 | H7: =данные!H118 -> 0 | I7: =данные!I118 -> 0 | J7: =данные!J118 -> 0 | K7: =данные!K118 -> 0 | ... DU7: =данные!DU118 -> 387417.33
A8: Постоянные расходы | C8: =SUM(D8:DU8) -> 38315960 | D8: =данные!D98 -> 0 | E8: =данные!E98 -> 0 | F8: =данные!F98 -> 0 | G8: =данные!G98 -> 0 | H8: =данные!H98 -> 0 | I8: =данные!I98 -> 0 | J8: =данные!J98 -> 0 | K8: =данные!K98 -> 0 | ... DU8: =данные!DU98 -> 276412.43
A9: Налог на имущество | C9: =SUM(D9:DU9) -> 8550389.4 | D9: =данные!D150 -> 0 | E9: =данные!E150 -> 0 | F9: =данные!F150 -> 0 | G9: =данные!G150 -> 0 | H9: =данные!H150 -> 0 | I9: =данные!I150 -> 0 | J9: =данные!J150 -> 0 | K9: =данные!K150 -> 0 | ... DU9: =данные!DU150 -> 0
A10: Прибыль от реализации | C10: =SUM(D10:DU10) -> 1.6541279e+09 | D10: =D6-SUM(D7:D9) -> 0 | E10: =E6-SUM(E7:E9) -> 0 | F10: =F6-SUM(F7:F9) -> 0 | G10: =G6-SUM(G7:G9) -> 0 | H10: =H6-SUM(H7:H9) -> 0 | I10: =I6-SUM(I7:I9) -> 0 | J10: =J6-SUM(J7:J9) -> 0 | K10: =K6-SUM(K7:K9) -> 0 | ... DU10: =DU6-SUM(DU7:DU9) -> 19053897
A11: Прочие доходы | C11: =SUM(D11:DU11) -> 0 | D11: 0 | E11: 0 | F11: 0 | G11: 0 | H11: 0 | I11: 0 | J11: 0 | K11: 0 | L11: 0 | M11: 0 | N11: 0 | O11: 0 | P11: 0 | Q11: 0 | R11: 0 | S11: 0 | T11: 0 | U11: 0 | V11: 0 | W11: 0 | X11: 0 | Y11: 0 | Z11: 0 | AA11: 0 | AB11: 0 | AC11: 0 | AD11: 0 | AE11: 0 | AF11: 0 | AG11: 0 | AH11: 0 | AI11: 0 | AJ11: 0 | AK11: 0 | AL11: 0 | AM11: 0 | AN11: 0 | AO11: 0 | AP11: 0 | AQ11: 0 | AR11: 0 | AS11: 0 | AT11: 0 | AU11: 0 | AV11: 0 | AW11: 0 | AX11: 0 | AY11: 0 | AZ11: 0 | BA11: 0 | BB11: 0 | BC11: 0 | BD11: 0 | BE11: 0 | BF11: 0 | BG11: 0 | BH11: 0 | BI11: 0 | BJ11: 0 | BK11: 0 | BL11: 0 | BM11: 0 | BN11: 0 | BO11: 0 | BP11: 0 | BQ11: 0 | BR11: 0 | BS11: 0 | BT11: 0 | BU11: 0 | BV11: 0 | BW11: 0 | BX11: 0 | BY11: 0 | BZ11: 0 | CA11: 0 | CB11: 0 | CC11: 0 | CD11: 0 | CE11: 0 | CF11: 0 | CG11: 0 | CH11: 0 | CI11: 0 | CJ11: 0 | CK11: 0 | CL11: 0 | CM11: 0 | CN11: 0 | CO11: 0 | CP11: 0 | CQ11: 0 | CR11: 0 | CS11: 0 | CT11: 0 | CU11: 0 | CV11: 0 | CW11: 0 | CX11: 0 | CY11: 0 | CZ11: 0 | DA11: 0 | DB11: 0 | DC11: 0 | DD11: 0 | DE11: 0 | DF11: 0 | DG11: 0 | DH11: 0 | DI11: 0 | DJ11: 0 | DK11: 0 | DL11: 0 | DM11: 0 | DN11: 0 | DO11: 0 | DP11: 0 | DQ11: 0 | DR11: 0 | DS11: 0 | DT11: 0 | DU11: 0
A12: Прочие расходы | C12: =SUM(D12:DU12) -> 84559.322 | D12: =(данные!D6+данные!D8)/(1+vat) -> 84559.322 | E12: =(данные!E6+данные!E8)/(1+vat) -> 0 | F12: =(данные!F6+данные!F8)/(1+vat) -> 0 | G12: =(данные!G6+данные!G8)/(1+vat) -> 0 | H12: =(данные!H6+данные!H8)/(1+vat) -> 0 | I12: =(данные!I6+данные!I8)/(1+vat) -> 0 | J12: =(данные!J6+данные!J8)/(1+vat) -> 0 | K12: =(данные!K6+данные!K8)/(1+vat) -> 0 | ... DU12: =(данные!DU6+данные!DU8)/(1+vat) -> 0
A13: EBITDA | C13: =SUM(D13:DU13) -> 1.6540434e+09 | D13: =D10+D11-D12 -> -84559.322 | E13: =E10+E11-E12 -> 0 | F13: =F10+F11-F12 -> 0 | G13: =G10+G11-G12 -> 0 | H13: =H10+H11-H12 -> 0 | I13: =I10+I11-I12 -> 0 | J13: =J10+J11-J12 -> 0 | K13: =K10+K11-K12 -> 0 | ... DU13: =DU10+DU11-DU12 -> 19053897
A14: Амортизация | C14: =SUM(D14:DU14) -> 55492828 | D14: =данные!D28 -> 0 | E14: =данные!E28 -> 0 | F14: =данные!F28 -> 0 | G14: =данные!G28 -> 0 | H14: =данные!H28 -> 0 | I14: =данные!I28 -> 28166.667 | J14: =данные!J28 -> 28166.667 | K14: =данные!K28 -> 28166.667 | ... DU14: =данные!DU28 -> 490089.92
A15: EBIT | C15: =SUM(D15:DU15) -> 1.5985505e+09 | D15: =D13-D14 -> -84559.322 | E15: =E13-E14 -> 0 | F15: =F13-F14 -> 0 | G15: =G13-G14 -> 0 | H15: =H13-H14 -> 0 | I15: =I13-I14 -> -28166.667 | J15: =J13-J14 -> -28166.667 | K15: =K13-K14 -> -28166.667 | ... DU15: =DU13-DU14 -> 18563808
A16: Проценты уплаченные | C16: =SUM(D16:DU16) -> 8789166.7 | D16: =кредит!D10 -> 0 | E16: =кредит!E10 -> 0 | F16: =кредит!F10 -> 0 | G16: =кредит!G10 -> 0 | H16: =кредит!H10 -> 0 | I16: =кредит!I10 -> 0 | J16: =кредит!J10 -> 0 | K16: =кредит!K10 -> 0 | ... DU16: =кредит!DU10 -> 0
A17: Налогооблагаемая прибыль | C17: =SUM(D17:DU17) -> 1.5897614e+09 | D17: =D15-D16 -> -84559.322 | E17: =E15-E16 -> 0 | F17: =F15-F16 -> 0 | G17: =G15-G16 -> 0 | H17: =H15-H16 -> 0 | I17: =I15-I16 -> -28166.667 | J17: =J15-J16 -> -28166.667 | K17: =K15-K16 -> -28166.667 | ... DU17: =DU15-DU16 -> 18563808
A18: Налог на прибыль | B18: =profittax -> 0.2 | C18: =SUM(D18:DU18) -> 3.1795227e+08 | D18: =MAX(0,D17*$B$18) -> 0 | E18: =MAX(0,$B$18*SUM($D$17:E17)-SUM($D$18:D18)) -> 0 | F18: =MAX(0,$B$18*SUM($D$17:F17)-SUM($D$18:E18)) -> 0 | G18: =MAX(0,$B$18*SUM($D$17:G17)-SUM($D$18:F18)) -> 0 | H18: =MAX(0,$B$18*SUM($D$17:H17)-SUM($D$18:G18)) -> 0 | I18: =MAX(0,$B$18*SUM($D$17:I17)-SUM($D$18:H18)) -> 0 | J18: =MAX(0,$B$18*SUM($D$17:J17)-SUM($D$18:I18)) -> 0 | K18: =MAX(0,$B$18*SUM($D$17:K17)-SUM($D$18:J18)) -> 0 | L18: =MAX(0,$B$18*SUM($D$17:L17)-SUM($D$18:K18)) -> 0 | ... DU18: =MAX(0,$B$18*SUM($D$17:DU17)-SUM($D$18:DT18)) -> 3712761.5
A19: Чистая прибыль | C19: =SUM(D19:DU19) -> 1.2718091e+09 | D19: =D15-D16-D18 -> -84559.322 | E19: =E15-E16-E18 -> 0 | F19: =F15-F16-F18 -> 0 | G19: =G15-G16-G18 -> 0 | H19: =H15-H16-H18 -> 0 | I19: =I15-I16-I18 -> -28166.667 | J19: =J15-J16-J18 -> -28166.667 | K19: =K15-K16-K18 -> -28166.667 | ... DU19: =DU15-DU16-DU18 -> 14851046
A22: млн. USD
A23: Прибыли/убытки | C23: Сумма | D23: 2014 | E23: 2015 | F23: 2016 | G23: 2017 | H23: 2018 | I23: 2019 | J23: 2020 | K23: 2021 | L23: 2022 | M23: 2023 | N23: 2024
A24: Выручка от реализации (без НДС) | C24: =SUM(D24:DU24) -> 5509.3171 | D24: =SUMIF($D$2:$DU$2,"="&D$23,$D4:$DU4)/1000000 -> 0 | E24: =SUMIF($D$2:$DU$2,"="&E$23,$D4:$DU4)/1000000 -> 193.51907 | F24: =SUMIF($D$2:$DU$2,"="&F$23,$D4:$DU4)/1000000 -> 482.09015 | G24: =SUMIF($D$2:$DU$2,"="&G$23,$D4:$DU4)/1000000 -> 506.19466 | H24: =SUMIF($D$2:$DU$2,"="&H$23,$D4:$DU4)/1000000 -> 531.50439 | I24: =SUMIF($D$2:$DU$2,"="&I$23,$D4:$DU4)/1000000 -> 558.07961 | J24: =SUMIF($D$2:$DU$2,"="&J$23,$D4:$DU4)/1000000 -> 585.98359 | K24: =SUMIF($D$2:$DU$2,"="&K$23,$D4:$DU4)/1000000 -> 615.28277 | ... N24: =SUMIF($D$2:$DU$2,"="&N$23,$D4:$DU4)/1000000 -> 712.26671
A25: Прямые расходы (без НДС) | C25: =SUM(D25:DU25) -> 3767.9449 | D25: =SUMIF($D$2:$DU$2,"="&D$23,$D5:$DU5)/1000000 -> 0 | E25: =SUMIF($D$2:$DU$2,"="&E$23,$D5:$DU5)/1000000 -> 133.05085 | F25: =SUMIF($D$2:$DU$2,"="&F$23,$D5:$DU5)/1000000 -> 331.14407 | G25: =SUMIF($D$2:$DU$2,"="&G$23,$D5:$DU5)/1000000 -> 347.29449 | H25: =SUMIF($D$2:$DU$2,"="&H$23,$D5:$DU5)/1000000 -> 364.25244 | I25: =SUMIF($D$2:$DU$2,"="&I$23,$D5:$DU5)/1000000 -> 382.05828 | J25: =SUMIF($D$2:$DU$2,"="&J$23,$D5:$DU5)/1000000 -> 400.75441 | K25: =SUMIF($D$2:$DU$2,"="&K$23,$D5:$DU5)/1000000 -> 420.38535 | ... N25: =SUMIF($D$2:$DU$2,"="&N$23,$D5:$DU5)/1000000 -> 485.36622
A26: Валовая прибыль | C26: =SUM(D26:DU26) -> 1741.3722 | D26: =D24-D25 -> 0 | E26: =E24-E25 -> 60.46822 | F26: =F24-F25 -> 150.94608 | G26: =G24-G25 -> 158.90016 | H26: =H24-H25 -> 167.25195 | I26: =I24-I25 -> 176.02133 | J26: =J24-J25 -> 185.22918 | K26: =K24-K25 -> 194.89741 | ... N26: =N24-N25 -> 226.90049
A27: ФОТ | C27: =SUM(D27:DU27) -> 40.377913 | D27: =SUMIF($D$2:$DU$2,"="&D$23,$D7:$DU7)/1000000 -> 0 | E27: =SUMIF($D$2:$DU$2,"="&E$23,$D7:$DU7)/1000000 -> 1.6415533 | F27: =SUMIF($D$2:$DU$2,"="&F$23,$D7:$DU7)/1000000 -> 3.994536 | G27: =SUMIF($D$2:$DU$2,"="&G$23,$D7:$DU7)/1000000 -> 4.071912 | H27: =SUMIF($D$2:$DU$2,"="&H$23,$D7:$DU7)/1000000 -> 4.149288 | I27: =SUMIF($D$2:$DU$2,"="&I$23,$D7:$DU7)/1000000 -> 4.226664 | J27: =SUMIF($D$2:$DU$2,"="&J$23,$D7:$DU7)/1000000 -> 4.30404 | K27: =SUMIF($D$2:$DU$2,"="&K$23,$D7:$DU7)/1000000 -> 4.381416 | ... N27: =SUMIF($D$2:$DU$2,"="&N$23,$D7:$DU7)/1000000 -> 4.613544
A28: Постоянные расходы | C28: =SUM(D28:DU28) -> 38.31596 | D28: =SUMIF($D$2:$DU$2,"="&D$23,$D8:$DU8)/1000000 -> 0 | E28: =SUMIF($D$2:$DU$2,"="&E$23,$D8:$DU8)/1000000 -> 2.0520621 | F28: =SUMIF($D$2:$DU$2,"="&F$23,$D8:$DU8)/1000000 -> 4.029322 | G28: =SUMIF($D$2:$DU$2,"="&G$23,$D8:$DU8)/1000000 -> 4.029322 | H28: =SUMIF($D$2:$DU$2,"="&H$23,$D8:$DU8)/1000000 -> 4.029322 | I28: =SUMIF($D$2:$DU$2,"="&I$23,$D8:$DU8)/1000000 -> 4.029322 | J28: =SUMIF($D$2:$DU$2,"="&J$23,$D8:$DU8)/1000000 -> 4.029322 | K28: =SUMIF($D$2:$DU$2,"="&K$23,$D8:$DU8)/1000000 -> 4.029322 | ... N28: =SUMIF($D$2:$DU$2,"="&N$23,$D8:$DU8)/1000000 -> 4.029322
A29: Налог на имущество | C29: =SUM(D29:DU29) -> 8.5503894 | D29: =SUMIF($D$2:$DU$2,"="&D$23,$D9:$DU9)/1000000 -> 0 | E29: =SUMIF($D$2:$DU$2,"="&E$23,$D9:$DU9)/1000000 -> 0.21940096 | F29: =SUMIF($D$2:$DU$2,"="&F$23,$D9:$DU9)/1000000 -> 1.4549854 | G29: =SUMIF($D$2:$DU$2,"="&G$23,$D9:$DU9)/1000000 -> 1.3123435 | H29: =SUMIF($D$2:$DU$2,"="&H$23,$D9:$DU9)/1000000 -> 1.1829597 | I29: =SUMIF($D$2:$DU$2,"="&I$23,$D9:$DU9)/1000000 -> 1.053576 | J29: =SUMIF($D$2:$DU$2,"="&J$23,$D9:$DU9)/1000000 -> 0.92419224 | K29: =SUMIF($D$2:$DU$2,"="&K$23,$D9:$DU9)/1000000 -> 0.7948085 | ... N29: =SUMIF($D$2:$DU$2,"="&N$23,$D9:$DU9)/1000000 -> 0.40665728
A30: Прибыль от реализации | C30: =SUM(D30:DU30) -> 1654.1279 | D30: =D26-SUM(D27:D29) -> 0 | E30: =E26-SUM(E27:E29) -> 56.555204 | F30: =F26-SUM(F27:F29) -> 141.46724 | G30: =G26-SUM(G27:G29) -> 149.48659 | H30: =H26-SUM(H27:H29) -> 157.89038 | I30: =I26-SUM(I27:I29) -> 166.71177 | J30: =J26-SUM(J27:J29) -> 175.97162 | K30: =K26-SUM(K27:K29) -> 185.69187 | ... N30: =N26-SUM(N27:N29) -> 217.85097
A31: Прочие доходы | C31: =SUM(D31:DU31) -> 0 | D31: =SUMIF($D$2:$DU$2,"="&D$23,$D11:$DU11)/1000000 -> 0 | E31: =SUMIF($D$2:$DU$2,"="&E$23,$D11:$DU11)/1000000 -> 0 | F31: =SUMIF($D$2:$DU$2,"="&F$23,$D11:$DU11)/1000000 -> 0 | G31: =SUMIF($D$2:$DU$2,"="&G$23,$D11:$DU11)/1000000 -> 0 | H31: =SUMIF($D$2:$DU$2,"="&H$23,$D11:$DU11)/1000000 -> 0 | I31: =SUMIF($D$2:$DU$2,"="&I$23,$D11:$DU11)/1000000 -> 0 | J31: =SUMIF($D$2:$DU$2,"="&J$23,$D11:$DU11)/1000000 -> 0 | K31: =SUMIF($D$2:$DU$2,"="&K$23,$D11:$DU11)/1000000 -> 0 | ... N31: =SUMIF($D$2:$DU$2,"="&N$23,$D11:$DU11)/1000000 -> 0
A32: Прочие расходы | C32: =SUM(D32:DU32) -> 0.084559322 | D32: =SUMIF($D$2:$DU$2,"="&D$23,$D12:$DU12)/1000000 -> 0.084559322 | E32: =SUMIF($D$2:$DU$2,"="&E$23,$D12:$DU12)/1000000 -> 0 | F32: =SUMIF($D$2:$DU$2,"="&F$23,$D12:$DU12)/1000000 -> 0 | G32: =SUMIF($D$2:$DU$2,"="&G$23,$D12:$DU12)/1000000 -> 0 | H32: =SUMIF($D$2:$DU$2,"="&H$23,$D12:$DU12)/1000000 -> 0 | I32: =SUMIF($D$2:$DU$2,"="&I$23,$D12:$DU12)/1000000 -> 0 | J32: =SUMIF($D$2:$DU$2,"="&J$23,$D12:$DU12)/1000000 -> 0 | K32: =SUMIF($D$2:$DU$2,"="&K$23,$D12:$DU12)/1000000 -> 0 | ... N32: =SUMIF($D$2:$DU$2,"="&N$23,$D12:$DU12)/1000000 -> 0
A33: EBITDA | C33: =SUM(D33:DU33) -> 1654.0434 | D33: =D30+D31-D32 -> -0.084559322 | E33: =E30+E31-E32 -> 56.555204 | F33: =F30+F31-F32 -> 141.46724 | G33: =G30+G31-G32 -> 149.48659 | H33: =H30+H31-H32 -> 157.89038 | I33: =I30+I31-I32 -> 166.71177 | J33: =J30+J31-J32 -> 175.97162 | K33: =K30+K31-K32 -> 185.69187 | ... N33: =N30+N31-N32 -> 217.85097
A34: Амортизация | C34: =SUM(D34:DU34) -> 55.492828 | D34: =SUMIF($D$2:$DU$2,"="&D$23,$D14:$DU14)/1000000 -> 0 | E34: =SUMIF($D$2:$DU$2,"="&E$23,$D14:$DU14)/1000000 -> 2.5631163 | F34: =SUMIF($D$2:$DU$2,"="&F$23,$D14:$DU14)/1000000 -> 5.8810791 | G34: =SUMIF($D$2:$DU$2,"="&G$23,$D14:$DU14)/1000000 -> 5.8810791 | H34: =SUMIF($D$2:$DU$2,"="&H$23,$D14:$DU14)/1000000 -> 5.8810791 | I34: =SUMIF($D$2:$DU$2,"="&I$23,$D14:$DU14)/1000000 -> 5.8810791 | J34: =SUMIF($D$2:$DU$2,"="&J$23,$D14:$DU14)/1000000 -> 5.8810791 | K34: =SUMIF($D$2:$DU$2,"="&K$23,$D14:$DU14)/1000000 -> 5.8810791 | ... N34: =SUMIF($D$2:$DU$2,"="&N$23,$D14:$DU14)/1000000 -> 5.8810791
A35: EBIT | C35: =SUM(D35:DU35) -> 1598.5505 | D35: =D33-D34 -> -0.084559322 | E35: =E33-E34 -> 53.992088 | F35: =F33-F34 -> 135.58616 | G35: =G33-G34 -> 143.60551 | H35: =H33-H34 -> 152.0093 | I35: =I33-I34 -> 160.83069 | J35: =J33-J34 -> 170.09054 | K35: =K33-K34 -> 179.81079 | ... N35: =N33-N34 -> 211.96989
A36: Проценты уплаченные | C36: =SUM(D36:DU36) -> 8.7891667 | D36: =SUMIF($D$2:$DU$2,"="&D$23,$D16:$DU16)/1000000 -> 0 | E36: =SUMIF($D$2:$DU$2,"="&E$23,$D16:$DU16)/1000000 -> 7.2338095 | F36: =SUMIF($D$2:$DU$2,"="&F$23,$D16:$DU16)/1000000 -> 1.5553571 | G36: =SUMIF($D$2:$DU$2,"="&G$23,$D16:$DU16)/1000000 -> 0 | H36: =SUMIF($D$2:$DU$2,"="&H$23,$D16:$DU16)/1000000 -> 0 | I36: =SUMIF($D$2:$DU$2,"="&I$23,$D16:$DU16)/1000000 -> 0 | J36: =SUMIF($D$2:$DU$2,"="&J$23,$D16:$DU16)/1000000 -> 0 | K36: =SUMIF($D$2:$DU$2,"="&K$23,$D16:$DU16)/1000000 -> 0 | ... N36: =SUMIF($D$2:$DU$2,"="&N$23,$D16:$DU16)/1000000 -> 0
A37: Налогооблагаемая прибыль | C37: =SUM(D37:DU37) -> 1589.7614 | D37: =SUMIF($D$2:$DU$2,"="&D$23,$D17:$DU17)/1000000 -> -0.084559322 | E37: =SUMIF($D$2:$DU$2,"="&E$23,$D17:$DU17)/1000000 -> 46.758278 | F37: =SUMIF($D$2:$DU$2,"="&F$23,$D17:$DU17)/1000000 -> 134.0308 | G37: =SUMIF($D$2:$DU$2,"="&G$23,$D17:$DU17)/1000000 -> 143.60551 | H37: =SUMIF($D$2:$DU$2,"="&H$23,$D17:$DU17)/1000000 -> 152.0093 | I37: =SUMIF($D$2:$DU$2,"="&I$23,$D17:$DU17)/1000000 -> 160.83069 | J37: =SUMIF($D$2:$DU$2,"="&J$23,$D17:$DU17)/1000000 -> 170.09054 | K37: =SUMIF($D$2:$DU$2,"="&K$23,$D17:$DU17)/1000000 -> 179.81079 | ... N37: =SUMIF($D$2:$DU$2,"="&N$23,$D17:$DU17)/1000000 -> 211.96989
